Workbook

Sheet all
A1: localID | B1: sendTime | C1: packetId | D1: receivedTime | E1: SNR | F1: RSSI | G1: latency | I1: packetID | J1: receivedTime | K1: RSSI | L1: SNR | N1: localID | O1: sendTIme | P1: packetId | Q1: receivedTime | R1: SNR | S1: RSSI | T1: latency | V1: packetId | W1: receivedTime | X1: SNR | Y1: RSSI
A2: 1 | B2: 1782221157 | C2: 3634305413 | D2: 1782221159.9821088 | E2: -138 | F2: -14.75 | G2: =D2-B2 -> 2.9821 | I2: 4290356512 | J2: 1782217172.619736 | K2: -140 | L2: -16.25 | N2: 1 | O2: 1.7821487e+09 | P2: 364721244 | Q2: 1782148663.2705617 | R2: -128 | S2: -5.75 | T2: =Q2-O2 -> 3.07828 | V2: 961753609 | W2: 1782147249.237996 | X2: -37 | Y2: 12.75
A3: 2 | B3: 1782221217 | C3: 2745722246 | D3: 1782221221.1092665 | E3: -137 | F3: -14.25 | G3: =D3-B3 -> 4.1092601 | I3: 729372961 | J3: 1782217229.071552 | N3: 17 | O3: 1.7821487e+09 | P3: 4030814316 | Q3: 1782148753.9836016 | R3: -138 | S3: -15 | T3: =Q3-O3 -> 12.0267 | V3: 59548170 | W3: 1782147254.155906 | X3: -38 | Y3: 12.75
A4: 3 | B4: 1782221277 | C4: 1637025159 | D4: 1782221287.2066689 | E4: -136 | F4: -12.75 | G4: =D4-B4 -> 10.20666 | I4: 729372961 | J4: 1782217231.9494898 | K4: -139 | L4: -14.5 | N4: 33 | O4: 1.7821488e+09 | P4: 4214166652 | Q4: 1782148830.521332 | R4: -139 | S4: -14.75 | T4: =Q4-O4 -> 6.8313801 | V4: 607901195 | W4: 1782147259.203906 | X4: -40 | Y4: 8.5
A5: 4 | B5: 1782221337 | C5: 4220239240 | D5: 1782221355.2040308 | E5: -135 | F5: -11.75 | G5: =D5-B5 -> 18.20403 | I5: 2255946018 | J5: 1782217289.3311958 | N5: 39 | O5: 1.7821489e+09 | P5: 2817523842 | Q5: 1782148866.407771 | R5: -132 | S5: -10.25 | T5: =Q5-O5 -> 12.06749 | V5: 2739012108 | W5: 1782147264.2968268 | X5: -40 | Y5: 10
A6: 6 | B6: 1782221457 | C6: 1470798218 | D6: 1782221460.246621 | E6: -134 | F6: -9.75 | G6: =D6-B6 -> 3.2466199 | I6: 2255946018 | J6: 1782217291.821974 | K6: -141 | L6: -16 | N6: 44 | O6: 1.7821489e+09 | P6: 3969881223 | Q6: 1782148882.9841857 | R6: -139 | S6: -16.5 | T6: =Q6-O6 -> 3.11168 | V6: 2054294029 | W6: 1782147269.315107 | X6: -41 | Y6: 10.5
A7: 7 | B7: 1782221517 | C7: 548419979 | D7: 1782221520.638365 | E7: -139 | F7: -15.75 | G7: =D7-B7 -> 3.63836 | I7: 2219626787 | J7: 1782217356.518823 | N7: 46 | O7: 1.7821489e+09 | P7: 1301657737 | Q7: 1782148893.196316 | R7: -140 | S7: -16.75 | T7: =Q7-O7 -> 3.09445 | V7: 1294283278 | W7: 1782147274.5624871 | X7: -42 | Y7: 13.75
A8: 9 | B8: 1782221638 | C8: 2627632525 | D8: 1782221641.8204472 | E8: -143 | F8: -18.5 | G8: =D8-B8 -> 3.8204401 | I8: 2219626787 | J8: 1782217359.1896162 | K8: -140 | L8: -15.5 | N8: 54 | O8: 1.7821489e+09 | P8: 1431559313 | Q8: 1782148952.541319 | R8: -140 | S8: -17.25 | T8: =Q8-O8 -> 21.57501 | V8: 2599896591 | W8: 1.7821473e+09 | X8: -44 | Y8: 13.5
A9: 10 | B9: 1782221698 | C9: 2046858638 | D9: 1782221700.8129692 | E9: -135 | F9: -11.25 | G9: =D9-B9 -> 2.8129599 | I9: 122175780 | J9: 1782217409.5785348 | N9: 56 | O9: 1.7821489e+09 | P9: 3440570515 | Q9: 1782148963.618582 | R9: -128 | S9: -7.75 | T9: =Q9-O9 -> 22.43525 | V9: 1371765264 | W9: 1782147284.652218 | X9: -41 | Y9: 10.25
A10: 12 | B10: 1782221818 | C10: 138802576 | D10: 1782221820.9275692 | E10: -134 | F10: -10 | G10: =D10-B10 -> 2.9275601 | I10: 3622173989 | J10: 1782217469.5103219 | N10: 57 | O10: 1.7821489e+09 | P10: 4073997460 | Q10: 1782148970.1675932 | R10: -128 | S10: -7.25 | T10: =Q10-O10 -> 23.87433 | V10: 2695563793 | W10: 1782147289.978676 | X10: -41 | Y10: 10.75
A11: 13 | B11: 1782221878 | C11: 993510801 | D11: 1782221888.2281592 | E11: -134 | F11: -10.5 | G11: =D11-B11 -> 10.22815 | I11: 3622173989 | J11: 1782217472.117717 | K11: -140 | L11: -15.25 | N11: 61 | O11: 1.782149e+09 | P11: 541416600 | Q11: 1782148990.2816827 | R11: -135 | S11: -12.5 | T11: =Q11-O11 -> 23.56466 | V11: 585779378 | W11: 1782149112.6562638
A12: 14 | B12: 1782221938 | C12: 4036419986 | D12: 1782221941.5256727 | E12: -132 | F12: -9.25 | G12: =D12-B12 -> 3.5256701 | I12: 1616640294 | J12: 1782217529.748328 | N12: 87 | O12: 1.7821491e+09 | P12: 585779378 | Q12: 1782149112.9570706 | R12: -132 | S12: -7.5 | T12: =Q12-O12 -> 13.36168 | V12: 585779378 | W12: 1782149115.4443672 | X12: -142 | Y12: -17.5
A13: 15 | B13: 1782221998 | C13: 1590730131 | D13: 1782222008.6364768 | E13: -134 | F13: -10.75 | G13: =D13-B13 -> 10.63647 | I13: 1616640294 | J13: 1782217532.114111 | K13: -140 | L13: -15 | N13: 99 | O13: 1.7821492e+09 | P13: 3113027774 | Q13: 1782149185.6303427 | R13: -135 | S13: -13 | T13: =Q13-O13 -> 24.66897 | V13: 2822975675 | W13: 1782149167.4398808
A14: 16 | B14: 1782222058 | C14: 2017960340 | D14: 1782222061.6838467 | E14: -136 | F14: -11.5 | G14: =D14-B14 -> 3.68384 | I14: 1832745255 | J14: 1782217589.620873 | N14: 103 | O14: 1.7821492e+09 | P14: 4096099522 | Q14: 1782149189.0686176 | R14: -138 | S14: -14.5 | T14: =Q14-O14 -> 7.6366498 | V14: 2015458496 | W14: 1782149175.299102
A15: 17 | B15: 1782222118 | C15: 3122014613 | D15: 1782222136.1432984 | E15: -139 | F15: -16.75 | G15: =D15-B15 -> 18.14329 | I15: 1832745255 | J15: 1782217593.1568232 | K15: -140 | L15: -14.75 | N15: 105 | O15: 1.7821492e+09 | P15: 2415827140 | Q15: 1782149195.2932267 | R15: -137 | S15: -13.5 | T15: =Q15-O15 -> 3.62728 | V15: 3113027774 | W15: 1782149185.3746612
A16: 18 | B16: 1782222178 | C16: 2308042134 | D16: 1782222189.0014262 | E16: -136 | F16: -12 | G16: =D16-B16 -> 11.00142 | I16: 2843938088 | J16: 1782217649.8648682 | N16: 106 | O16: 1.7821492e+09 | P16: 2007240901 | Q16: 1782149202.4927642 | R16: -133 | S16: -9.5 | T16: =Q16-O16 -> 5.7126501 | V16: 3113027774 | W16: 1782149187.4433799 | X16: -144 | Y16: -19
A17: 21 | B17: 1782222359 | C17: 2806242713 | D17: 1782222362 | E17: -134 | F17: -11.25 | G17: =D17-B17 -> 3 | I17: 2843938088 | J17: 1.7822177e+09 | K17: -140 | L17: -15 | N17: 117 | O17: 1.7821493e+09 | P17: 1717115088 | Q17: 1782149258.0576057 | R17: -135 | S17: -11.75 | T17: =Q17-O17 -> 5.0532901 | V17: 4096099522 | W17: 1782149191.0130088 | X17: -139 | Y17: -15.75
A18: 24 | B18: 1782222539 | C18: 1923212700 | D18: 1782222549.4673004 | E18: -132 | F18: -9 | G18: =D18-B18 -> 10.4673 | I18: 2884938026 | J18: 1782217770.1730208 | N18: 116 | O18: 1.7821492e+09 | P18: 1487864015 | Q18: 1782149270.0427184 | R18: -134 | S18: -10.5 | T18: =Q18-O18 -> 22.14601 | V18: 2415827140 | W18: 1782149194.9885151
A19: 25 | B19: 1782222599 | C19: 3824428445 | D19: 1782222616.636571 | E19: -135 | F19: -13 | G19: =D19-B19 -> 17.63657 | I19: 2884938026 | J19: 1782217774.4752781 | K19: -144 | L19: -18.5 | N19: 138 | O19: 1.7821494e+09 | P19: 1877002469 | Q19: 1782149383.7143095 | R19: -133 | S19: -9 | T19: =Q19-O19 -> 23.3611 | V19: 2415827140 | W19: 1782149197.528825 | X19: -141 | Y19: -16.5
A20: 26 | B20: 1782222659 | C20: 3203792286 | D20: 1782222662.611674 | E20: -136 | F20: -11.5 | G20: =D20-B20 -> 3.61167 | I20: 462384427 | J20: 1782217830.0631301 | N20: 167 | O20: 1.7821495e+09 | P20: 1242344706 | Q20: 1782149532.1743305 | R20: -136 | S20: -12.5 | T20: =Q20-O20 -> 23.55036 | V20: 2007240901 | W20: 1782149211.873712 | X20: -144 | Y20: -19.75
A21: 28 | B21: 1782222780 | C21: 2898474400 | D21: 1782222782.8278298 | E21: -141 | F21: -17.75 | G21: =D21-B21 -> 2.8278201 | I21: 3057522988 | J21: 1782217891.0773602 | N21: 169 | O21: 1.7821495e+09 | P21: 124996868 | Q21: 1782149533.410504 | R21: -131 | S21: -8.25 | T21: =Q21-O21 -> 14.5675 | V21: 4156321992 | W21: 1782149233.2025669
A22: 29 | B22: 1782222840 | C22: 3907392929 | D22: 1782222842.8819034 | E22: -141 | F22: -17 | G22: =D22-B22 -> 2.8819001 | I22: 3836721453 | J22: 1782217950.4662669 | N22: 173 | O22: 1.7821495e+09 | P22: 3524587784 | Q22: 1782149548.6720688 | R22: -128 | S22: -4.5 | T22: =Q22-O22 -> 9.37239 | V22: 1242344706 | W22: 1782149531.874839
A23: 34 | B23: 1782223140 | C23: 2075148710 | D23: 1782223143.3792925 | E23: -139 | F23: -16.25 | G23: =D23-B23 -> 3.3792901 | I23: 3836721453 | J23: 1782217952.997376 | K23: -143 | L23: -17.5 | N23: 174 | O23: 1.7821495e+09 | P23: 1883863305 | Q23: 1782149558.8464105 | R23: -134 | S23: -9.75 | T23: =Q23-O23 -> 14.44342 | V23: 1242344706 | W23: 1782149543.9179919 | X23: -144 | Y23: -20
A24: 37 | B24: 1782223321 | C24: 2064934313 | D24: 1782223331.740758 | E24: -138 | F24: -14 | G24: =D24-B24 -> 10.74075 | I24: 1399481646 | J24: 1782218017.689475 | N24: 176 | O24: 1.7821496e+09 | P24: 684951819 | Q24: 1782149569.1566632 | R24: -133 | S24: -10 | T24: =Q24-O24 -> 14.52887 | V24: 3524587784 | W24: 1782149548.373067
A25: 40 | B25: 1782223501 | C25: 941753772 | D25: 1782223505.6866405 | E25: -143 | F25: -18.5 | G25: =D25-B25 -> 4.68664 | I25: 1399481646 | J25: 1782218021.315799 | K25: -144 | L25: -18.75 | N25: 178 | O25: 1.7821496e+09 | P25: 1164962061 | Q25: 1782149571.8314078 | R25: -133 | S25: -9.75 | T25: =Q25-O25 -> 6.9763 | V25: 3524587784 | W25: 1782149552.405238 | X25: -142 | Y25: -17.75
A26: 45 | B26: 1782223801 | C26: 2579889 | D26: 1782223811.8402867 | E26: -136 | F26: -12.25 | G26: =D26-B26 -> 10.84028 | I26: 1647871280 | J26: 1782218130.660876 | N26: 177 | O26: 1.7821496e+09 | P26: 315475212 | Q26: 1782149586.0796862 | R26: -137 | S26: -13.5 | T26: =Q26-O26 -> 26.33812 | V26: 684951819 | W26: 1782149568.8569658
A27: 46 | B27: 1782223862 | C27: 1218838962 | D27: 1782223864.8105066 | E27: -136 | F27: -12.25 | G27: =D27-B27 -> 2.8104999 | I27: 180512049 | J27: 1782218197.9324028 | N27: 183 | O27: 1.7821496e+09 | P27: 3439140114 | Q27: 1782149605.1455486 | R27: -134 | S27: -9.5 | T27: =Q27-O27 -> 14.7002 | V27: 1883863305 | W27: 1782149570.445656
A28: 48 | B28: 1782223982 | C28: 3812074932 | D28: 1782223999.7891912 | E28: -125 | F28: -4.25 | G28: =D28-B28 -> 17.78919 | I28: 180512049 | J28: 1782218200.434185 | K28: -143 | L28: -17 | N28: 187 | O28: 1.7821496e+09 | P28: 1398266134 | Q28: 1782149626.5938609 | R28: -138 | S28: -14.25 | T28: =Q28-O28 -> 15.70437 | V28: 684951819 | W28: 1782149581.5760121 | X28: -141 | Y28: -17
A29: 53 | B29: 1782224282 | C29: 706235833 | D29: 1782224292.7444775 | E29: -123 | F29: -2 | G29: =D29-B29 -> 10.74447 | I29: 586396978 | J29: 1782218250.7319438 | N29: 189 | O29: 1.7821496e+09 | P29: 728140056 | Q29: 1782149635.5909226 | R29: -137 | S29: -14.25 | T29: =Q29-O29 -> 14.47046 | V29: 315475212 | W29: 1782149586.060395
A30: 55 | B30: 1782224403 | C30: 1883827643 | D30: 1782224420.3221204 | E30: -125 | F30: -3 | G30: =D30-B30 -> 17.32212 | I30: 586396978 | J30: 1782218254.056912 | K30: -141 | L30: -17 | N30: 192 | O30: 1.7821496e+09 | P30: 2072673563 | Q30: 1782149657.4102714 | R30: -134 | S30: -10 | T30: =Q30-O30 -> 20.96068 | V30: 315475212 | W30: 1782149589.1770291 | X30: -143 | Y30: -17.5
A31: 57 | B31: 1782224523 | C31: 262309309 | D31: 1782224540.7139227 | E31: -125 | F31: -4 | G31: =D31-B31 -> 17.71392 | I31: 3659877683 | J31: 1.7822183e+09 | K31: -143 | L31: -18 | N31: 196 | O31: 1.7821497e+09 | P31: 1967429919 | Q31: 1782149662.3347805 | R31: -133 | S31: -10 | T31: =Q31-O31 -> 5.4530201 | V31: 1164962061 | W31: 1782149591.049441
I32: 1679633716 | J32: 1782218385.649079 | N32: 201 | O32: 1.7821497e+09 | P32: 1822588196 | Q32: 1782149686.369043 | R32: -133 | S32: -9 | T32: =Q32-O32 -> 3.9217501 | V32: 3439140114 | W32: 1782149607.9300091 | X32: -143 | Y32: -19.25
A33: Avg DR | B33: Avg Latency (s) | C33: Bidirectional | D33: Bidirectional % | I33: 3683733813 | J33: 1782218431.0898361 | N33: 202 | O33: 1.7821497e+09 | P33: 25142565 | Q33: 1782149711.4028258 | R33: -140 | S33: -16.5 | T33: =Q33-O33 -> 23.83854 | V33: 39774485 | W33: 1782149614.461735
A34: =(31/60)*100 -> 51.666667 | B34: =AVERAGE(G2:G31) -> 8.1873084 | C34: {=SUMPRODUCT(--(COUNTIF(I2:I119, C2:C31)>0))} -> 28 | D34: =(C34/31)*100 -> 90.322581 | I34: 297649463 | J34: 1782218551.3423748 | N34: 205 | O34: 1.7821497e+09 | P34: 3820752168 | Q34: 1782149725.023279 | R34: -132 | S34: -10.25 | T34: =Q34-O34 -> 22.11281 | V34: 1398266134 | W34: 1782149626.526565
I35: 297649463 | J35: 1782218554.263131 | K35: -142 | L35: -17.5 | N35: 210 | O35: 1.7821497e+09 | P35: 4201198893 | Q35: 1782149742.8126848 | R35: -133 | S35: -10.75 | T35: =Q35-O35 -> 14.32523 | V35: 1398266134 | W35: 1782149629.572354 | X35: -144 | Y35: -18.75
I36: 1285018936 | J36: 1.7822186e+09 | N36: 222 | O36: 1.7821498e+09 | P36: 753751353 | Q36: 1782149814.7414372 | R36: -138 | S36: -14.5 | T36: =Q36-O36 -> 24.89843 | V36: 728140056 | W36: 1782149635.2712379
I37: 1321018681 | J37: 1782218686.289185 | N37: 226 | O37: 1.7821498e+09 | P37: 3769875773 | Q37: 1782149834.0405805 | R37: -130 | S37: -7.75 | T37: =Q37-O37 -> 23.72895 | V37: 2072673563 | W37: 1782149657.3317518
I38: 1107982650 | J38: 1782218746.397982 | N38: 229 | O38: 1.7821498e+09 | P38: 920943936 | Q38: 1782149839.3932524 | R38: -130 | S38: -6.75 | T38: =Q38-O38 -> 13.74726 | V38: 1967429919 | W38: 1782149662.010369
I39: 3052593467 | J39: 1782218806.381904 | N39: 232 | O39: 1.7821498e+09 | P39: 3149403459 | Q39: 1782149846.3551116 | R39: -129 | S39: -6.25 | T39: =Q39-O39 -> 5.3701799 | V39: 1822588196 | W39: 1782149686.387064
I40: 3052593467 | J40: 1782218808.794261 | K40: -143 | L40: -18 | N40: 235 | O40: 1.7821499e+09 | P40: 3036657990 | Q40: 1782149868.7771063 | R40: -135 | S40: -11.75 | T40: =Q40-O40 -> 12.44305 | V40: 920943936 | W40: 1782149839.070962
...

Sheet Final Results
A1: Test Type | B1: Avg DR | C1: Avg Latency (s) | D1: ACK Received | E1: Bidirectional %
A2: 1 minute | B2: =(31/60)*100 -> 51.666667 | C2: =AVERAGE(all!G2:G31) -> 8.1873084 | D2: {=SUMPRODUCT(--( COUNTIF(all!I2:I119,all!C2:C31)>0))} -> 28 | E2: =(D2/31)*100 -> 90.322581
A3: 5 second | B3: =(COUNT(all!N2:N79)/300)*100 -> 26 | C3: =AVERAGE(all!T2:T79) -> 15.022216 | D3: {=SUMPRODUCT(--( COUNTIF(all!V2:V99,all!P2:P79)>0))} -> 53 | E3: =(D3/COUNT(all!N2:N79))*100 -> 67.948718
