Workbook

Sheet 5sec_morning
A1: packetID | B1: fromID | C1: toID | D1: relayNode | E1: hops | F1: localID | G1: sendTIme | H1: RSSI (last hop) | I1: SNR (last hop)
A2: 251032843 | B2: !6c73daa0 | C2: !dadfb8d4 | D2: 200 | E2: 2 | F2: 2 | G2: 1.782995e+09 | H2: -138 | I2: -13
A3: 724250890 | B3: !6c73daa0 | C3: !dadfb8d4 | D3: 8 | E3: 2 | F3: 1 | G3: 1.782995e+09 | H3: -134 | I3: -9.75
A4: 1831836940 | B4: !6c73daa0 | C4: !dadfb8d4 | D4: 200 | E4: 2 | F4: 3 | G4: 1.782995e+09 | H4: -139 | I4: -13.5
A5: 2642302221 | B5: !6c73daa0 | C5: !dadfb8d4 | D5: 8 | E5: 2 | F5: 4 | G5: 1.782995e+09 | H5: -133 | I5: -8.5
A6: 421895438 | B6: !6c73daa0 | C6: !dadfb8d4 | D6: 200 | E6: 2 | F6: 5 | G6: 1.782995e+09 | H6: -139 | I6: -14.5
A7: 1050147087 | B7: !6c73daa0 | C7: !dadfb8d4 | D7: 200 | E7: 2 | F7: 6 | G7: 1.782995e+09 | H7: -139 | I7: -14
A8: 79485200 | B8: !6c73daa0 | C8: !dadfb8d4 | D8: 200 | E8: 2 | F8: 7 | G8: 1.782995e+09 | H8: -139 | I8: -13.75
A9: 263431441 | B9: !6c73daa0 | C9: !dadfb8d4 | D9: 200 | E9: 2 | F9: 8 | G9: 1.782995e+09 | H9: -139 | I9: -13.75
A10: 3987654930 | B10: !6c73daa0 | C10: !dadfb8d4 | D10: 8 | E10: 2 | F10: 9 | G10: 1.7829951e+09 | H10: -134 | I10: -9.75
A11: 1629228307 | B11: !6c73daa0 | C11: !dadfb8d4 | D11: 200 | E11: 2 | F11: 10 | G11: 1.7829951e+09 | H11: -138 | I11: -13.75
A12: 1398049044 | B12: !6c73daa0 | C12: !dadfb8d4 | D12: 200 | E12: 2 | F12: 11 | G12: 1.7829951e+09 | H12: -138 | I12: -13
A13: 2209050901 | B13: !6c73daa0 | C13: !dadfb8d4 | D13: 200 | E13: 2 | F13: 12 | G13: 1.7829951e+09 | H13: -138 | I13: -13.25
... A38: 3707590971 | B38: !6c73daa0 | C38: !dadfb8d4 | D38: 200 | E38: 2 | F38: 50 | G38: 1.7829953e+09 | H38: -139 | I38: -14

Sheet 5sec_morning_ACK
A2: 724250890 | B2: 1782995013.6558988
A3: 251032843 | B3: 1.782995e+09
A4: 724250890 | B4: 1782995028.246974 | C4: -145 | D4: -19.75
A5: 1831836940 | B5: 1782995028.983136
A6: 2642302221 | B6: 1782995036.8787909
A7: 421895438 | B7: 1782995039.150548
A8: 1050147087 | B8: 1782995040.416229
A9: 2642302221 | B9: 1782995044.748644 | C9: -112 | D9: 7.25
A10: 421895438 | B10: 1782995046.0190248 | C10: -143 | D10: -20
A11: 79485200 | B11: 1782995051.072513
A12: 1050147087 | B12: 1.7829951e+09 | C12: -113 | D12: 6.75
A13: 263431441 | B13: 1782995065.285951
A14: 263431441 | B14: 1782995074.532823 | C14: -113 | D14: 7.25
A15: 1629228307 | B15: 1782995095.406804 | C15: -113 | D15: 8.5
A16: 1398049044 | B16: 1782995112.5259562 | C16: -113 | D16: 5.5
A17: 4289831195 | B17: 1782995200.696197 | C17: -112 | D17: 7.5
A18: 306826525 | B18: 1782995224.4149172 | C18: -115 | D18: 7.25
A19: 3361833247 | B19: 1782995236.0599868 | C19: -114 | D19: 6.5

Sheet 20sec_morning
A1: packetID | B1: fromID | C1: toID | D1: relayNode | E1: hops | F1: localID | G1: sendTIme | H1: RSSI (last hop) | I1: SNR (last hop)
A2: 4164637577 | B2: !6c73daa0 | C2: !dadfb8d4 | D2: 200 | E2: 2 | F2: 1 | G2: 1.7829965e+09 | H2: -138 | I2: -13.5
A3: 3434371978 | B3: !6c73daa0 | C3: !dadfb8d4 | D3: 200 | E3: 2 | F3: 2 | G3: 1.7829965e+09 | H3: -139 | I3: -13.5
A4: 2467580811 | B4: !6c73daa0 | C4: !dadfb8d4 | D4: 200 | E4: 2 | F4: 3 | G4: 1.7829965e+09 | H4: -138 | I4: -13.25
A5: 3878669196 | B5: !6c73daa0 | C5: !dadfb8d4 | D5: 200 | E5: 2 | F5: 4 | G5: 1.7829965e+09 | H5: -140 | I5: -13.75
A6: 3682053005 | B6: !6c73daa0 | C6: !dadfb8d4 | D6: 200 | E6: 2 | F6: 5 | G6: 1.7829966e+09 | H6: -138 | I6: -14
A7: 2050350990 | B7: !6c73daa0 | C7: !dadfb8d4 | D7: 200 | E7: 2 | F7: 6 | G7: 1.7829966e+09 | H7: -138 | I7: -13.75
A8: 2221574031 | B8: !6c73daa0 | C8: !dadfb8d4 | D8: 200 | E8: 2 | F8: 7 | G8: 1.7829966e+09 | H8: -139 | I8: -13.75
A9: 4009341840 | B9: !6c73daa0 | C9: !dadfb8d4 | D9: 200 | E9: 2 | F9: 8 | G9: 1.7829966e+09 | H9: -139 | I9: -13.75
A10: 300799889 | B10: !6c73daa0 | C10: !dadfb8d4 | D10: 200 | E10: 2 | F10: 9 | G10: 1.7829966e+09 | H10: -139 | I10: -14
A11: 744574866 | B11: !6c73daa0 | C11: !dadfb8d4 | D11: 200 | E11: 2 | F11: 10 | G11: 1.7829967e+09 | H11: -137 | I11: -13.25
A12: 487651219 | B12: !6c73daa0 | C12: !dadfb8d4 | D12: 200 | E12: 2 | F12: 11 | G12: 1.7829967e+09 | H12: -138 | I12: -14
A13: 4234804116 | B13: !6c73daa0 | C13: !dadfb8d4 | D13: 200 | E13: 2 | F13: 12 | G13: 1.7829967e+09 | H13: -139 | I13: -13.5
... A50: 1840741306 | B50: !6c73daa0 | C50: !dadfb8d4 | D50: 200 | E50: 2 | F50: 50 | G50: 1.7829975e+09 | H50: -136 | I50: -12.75

Sheet 20sec_morning_ACK
A2: 3963149602 | B2: 1782996472.134261 | C2: -114 | D2: 6.75
A3: 2206184761 | B3: 1782996472.195532 | C3: -114 | D3: 7.5
A4: 3576684836 | B4: 1782996472.258548 | C4: -144 | D4: -20
A5: 4164637577 | B5: 1782996482.526283
A6: 4164637577 | B6: 1782996491.756474 | C6: -117 | D6: 5.75
A7: 3434371978 | B7: 1782996495.676743
A8: 3434371978 | B8: 1782996508.025467 | C8: -116 | D8: 5.25
A9: 2467580811 | B9: 1782996530.524556
A10: 3878669196 | B10: 1782996535.337505
A11: 2467580811 | B11: 1782996538.220339 | C11: -117 | D11: 5.25
A12: 3878669196 | B12: 1782996543.333996 | C12: -144 | D12: -18.75
A13: 3682053005 | B13: 1782996555.0813491
A14: 3682053005 | B14: 1782996568.001615 | C14: -115 | D14: 5.25
A15: 2050350990 | B15: 1782996575.436586
A16: 2050350990 | B16: 1782996581.434752 | C16: -115 | D16: 5.25
A17: 2221574031 | B17: 1782996595.4913301
A18: 2221574031 | B18: 1782996602.4122581 | C18: -114 | D18: 5.75
A19: 4009341840 | B19: 1782996616.755393
A20: 4009341840 | B20: 1782996622.914189 | C20: -116 | D20: 5.5
A21: 300799889 | B21: 1782996637.739819
A22: 300799889 | B22: 1782996644.8979461 | C22: -117 | D22: 5.5
A23: 744574866 | B23: 1.7829967e+09
A24: 744574866 | B24: 1782996663.874985 | C24: -116 | D24: 5
A25: 487651219 | B25: 1782996676.116554
A26: 487651219 | B26: 1782996682.144149 | C26: -115 | D26: 5.75
A27: 4234804116 | B27: 1782996696.710251
A28: 4234804116 | B28: 1782996703.323147 | C28: -115 | D28: 5.25
A29: 2144911253 | B29: 1782996717.417622
A30: 2144911253 | B30: 1782996723.598328 | C30: -116 | D30: 5.75
A31: 1451287446 | B31: 1782996737.2346072
A32: 1451287446 | B32: 1782996743.173223 | C32: -115 | D32: 4.5
A33: 3265542039 | B33: 1782996756.470345
A34: 3265542039 | B34: 1782996762.7506409 | C34: -114 | D34: 6.25
A35: 2312718232 | B35: 1782996777.871966
A36: 2312718232 | B36: 1782996783.450469 | C36: -115 | D36: 4.75
A37: 2607583129 | B37: 1782996796.895776
A38: 2607583129 | B38: 1782996803.485906 | C38: -116 | D38: 5
A39: 3980612506 | B39: 1782996819.109199
A40: 2227650459 | B40: 1782996837.2447948
A41: 2227650459 | B41: 1782996845.902996 | C41: -144 | D41: -19.25
...

Sheet 40sec_morning
A1: packetID | B1: fromID | C1: toID | D1: relayNode | E1: hops | F1: localID | G1: sendTIme | H1: RSSI (last hop) | I1: SNR (last hop)
A2: 2068239737 | B2: !6c73daa0 | C2: !dadfb8d4 | D2: 200 | E2: 2 | F2: 1 | G2: 1.7829987e+09 | H2: -140 | I2: -14.5
A3: 3977495930 | B3: !6c73daa0 | C3: !dadfb8d4 | D3: 200 | E3: 2 | F3: 2 | G3: 1.7829987e+09 | H3: -140 | I3: -13.5
A4: 2700889467 | B4: !6c73daa0 | C4: !dadfb8d4 | D4: 200 | E4: 2 | F4: 3 | G4: 1.7829988e+09 | H4: -138 | I4: -13.75
A5: 3513514364 | B5: !6c73daa0 | C5: !dadfb8d4 | D5: 200 | E5: 2 | F5: 4 | G5: 1.7829988e+09 | H5: -139 | I5: -14.5
A6: 2023546237 | B6: !6c73daa0 | C6: !dadfb8d4 | D6: 200 | E6: 2 | F6: 5 | G6: 1.7829988e+09 | H6: -138 | I6: -13.25
A7: 3117243774 | B7: !6c73daa0 | C7: !dadfb8d4 | D7: 200 | E7: 2 | F7: 6 | G7: 1.7829989e+09 | H7: -140 | I7: -14.5
A8: 1509996927 | B8: !6c73daa0 | C8: !dadfb8d4 | D8: 200 | E8: 2 | F8: 7 | G8: 1.7829989e+09 | H8: -140 | I8: -14.5
A9: 2272942464 | B9: !6c73daa0 | C9: !dadfb8d4 | D9: 200 | E9: 2 | F9: 8 | G9: 1.782999e+09 | H9: -140 | I9: -14.5
A10: 2500461953 | B10: !6c73daa0 | C10: !dadfb8d4 | D10: 200 | E10: 2 | F10: 9 | G10: 1.782999e+09 | H10: -139 | I10: -13.75
A11: 432717186 | B11: !6c73daa0 | C11: !dadfb8d4 | D11: 200 | E11: 2 | F11: 10 | G11: 1.782999e+09 | H11: -138 | I11: -13
A12: 1073852803 | B12: !6c73daa0 | C12: !dadfb8d4 | D12: 200 | E12: 2 | F12: 11 | G12: 1.7829991e+09 | H12: -139 | I12: -15
A13: 155224452 | B13: !6c73daa0 | C13: !dadfb8d4 | D13: 200 | E13: 2 | F13: 12 | G13: 1.7829991e+09 | H13: -138 | I13: -14
... A51: 1733024170 | B51: !6c73daa0 | C51: !dadfb8d4 | D51: 200 | E51: 2 | F51: 50 | G51: 1.7830006e+09 | H51: -138 | I51: -13.25

Sheet 40sec_morning_ACK
A2: 2068239737 | B2: 1782998687.821128
A3: 2068239737 | B3: 1782998693.297657 | C3: -114 | D3: 6.5
A4: 3977495930 | B4: 1782998727.583183
A5: 3977495930 | B5: 1782998732.000213 | C5: -143 | D5: -19.25
A6: 2700889467 | B6: 1782998766.651723
A7: 2700889467 | B7: 1782998773.9098089 | C7: -114 | D7: 8
A8: 3513514364 | B8: 1782998806.710054
A9: 3513514364 | B9: 1782998812.604222 | C9: -113 | D9: 6.25
A10: 2023546237 | B10: 1782998847.1004548
A11: 2023546237 | B11: 1782998852.656597 | C11: -144 | D11: -20
A12: 3117243774 | B12: 1782998887.8524532
A13: 3117243774 | B13: 1782998894.6500301 | C13: -113 | D13: 7.5
A14: 1509996927 | B14: 1782998927.791605
A15: 1509996927 | B15: 1782998934.689466 | C15: -113 | D15: 8
A16: 2272942464 | B16: 1782998968.0768058
A17: 2272942464 | B17: 1782998979.2713711 | C17: -145 | D17: -19.75
A18: 2500461953 | B18: 1782999008.669558
A19: 2500461953 | B19: 1782999012.614944 | C19: -144 | D19: -20
A20: 432717186 | B20: 1.782999e+09
A21: 432717186 | B21: 1782999055.3208718 | C21: -114 | D21: 7.25
A22: 1073852803 | B22: 1.7829991e+09
A23: 1073852803 | B23: 1782999093.624589 | C23: -145 | D23: -19.75
A24: 155224452 | B24: 1782999130.8877969
A25: 155224452 | B25: 1782999136.899926 | C25: -116 | D25: 8
A26: 2023571845 | B26: 1782999167.730171
A27: 2023571845 | B27: 1782999173.488053 | C27: -142 | D27: -19.25
A28: 25504134 | B28: 1782999208.498395
A29: 25504134 | B29: 1782999215.630698 | C29: -115 | D29: 7
A30: 414709127 | B30: 1782999250.999865
A31: 414709127 | B31: 1782999257.724328 | C31: -113 | D31: 8.75
A32: 2233118088 | B32: 1782999288.850498
A33: 2233118088 | B33: 1782999295.460057 | C33: -113 | D33: 7
A34: 3737309577 | B34: 1782999328.128492
A35: 3737309577 | B35: 1782999334.677619 | C35: -113 | D35: 8.25
A36: 2263938442 | B36: 1782999370.7804868
A37: 2263938442 | B37: 1782999378.486617 | C37: -115 | D37: 6.5
A38: 3103342987 | B38: 1782999409.406267
A39: 3103342987 | B39: 1.7829994e+09 | C39: -113 | D39: 7.25
A40: 2378580364 | B40: 1782999448.4864929
A41: 2378580364 | B41: 1782999454.655773 | C41: -115 | D41: 5.5
...

Sheet 1min_morning
A1: packetID | B1: fromID | C1: toID | D1: relayNode | E1: hops | F1: localID | G1: sendTime | H1: RSSI | I1: SNR
A2: 1801894923 | B2: !6c73daa0 | C2: !dadfb8d4 | D2: 200 | E2: 2 | F2: 1 | G2: 1.7830019e+09 | H2: -138 | I2: -14
A3: 3615723532 | B3: !6c73daa0 | C3: !dadfb8d4 | D3: 200 | E3: 2 | F3: 2 | G3: 1.783002e+09 | H3: -140 | I3: -14.75
A4: 28907533 | B4: !6c73daa0 | C4: !dadfb8d4 | D4: 204 | E4: 1 | F4: 3 | G4: 1.783002e+09 | H4: -145 | I4: -19.5
A5: 1153120270 | B5: !6c73daa0 | C5: !dadfb8d4 | D5: 200 | E5: 2 | F5: 4 | G5: 1.7830021e+09 | H5: -138 | I5: -14
A6: 3516863503 | B6: !6c73daa0 | C6: !dadfb8d4 | D6: 200 | E6: 2 | F6: 5 | G6: 1.7830021e+09 | H6: -140 | I6: -16
A7: 3414279184 | B7: !6c73daa0 | C7: !dadfb8d4 | D7: 200 | E7: 2 | F7: 6 | G7: 1.7830022e+09 | H7: -140 | I7: -15.25
A8: 1281884177 | B8: !6c73daa0 | C8: !dadfb8d4 | D8: 200 | E8: 2 | F8: 7 | G8: 1.7830023e+09 | H8: -138 | I8: -12.75
A9: 3002419218 | B9: !6c73daa0 | C9: !dadfb8d4 | D9: 200 | E9: 2 | F9: 8 | G9: 1.7830023e+09 | H9: -141 | I9: -16
A10: 1881288723 | B10: !6c73daa0 | C10: !dadfb8d4 | D10: 200 | E10: 2 | F10: 9 | G10: 1.7830024e+09 | H10: -139 | I10: -13.5
A11: 3691296788 | B11: !6c73daa0 | C11: !dadfb8d4 | D11: 200 | E11: 2 | F11: 10 | G11: 1.7830024e+09 | H11: -138 | I11: -12.5
A12: 2849300501 | B12: !6c73daa0 | C12: !dadfb8d4 | D12: 200 | E12: 2 | F12: 11 | G12: 1.7830025e+09 | H12: -139 | I12: -14.5
A13: 3123426326 | B13: !6c73daa0 | C13: !dadfb8d4 | D13: 204 | E13: 1 | F13: 12 | G13: 1.7830026e+09 | H13: -146 | I13: -20.75
... A51: 4130425916 | B51: !6c73daa0 | C51: !dadfb8d4 | D51: 99 | E51: 2 | F51: 50 | G51: 1.7830048e+09 | H51: -103 | I51: 9

Sheet 1min_morning_ACK
A1: 1801894923 | B1: 1783001900.099304
A2: 3615723532 | B2: 1783001958.730546
A3: 3615723532 | B3: 1783001973.884809 | C3: -114 | D3: 7
A4: 28907533 | B4: 1783002019.5805178
A5: 28907533 | B5: 1.783002e+09 | C5: -144 | D5: -19.75
A6: 1153120270 | B6: 1783002079.972933
A7: 1153120270 | B7: 1783002084.145686 | C7: -144 | D7: -19.5
A8: 1486026959 | B8: 1783002094.8604789 | C8: -83 | D8: 10.5
A9: 3516863503 | B9: 1783002140.0585291
A10: 3516863503 | B10: 1783002146.928237 | C10: -113 | D10: 9
A11: 3414279184 | B11: 1783002200.109644
A12: 3414279184 | B12: 1783002208.588971 | C12: -115 | D12: 6.25
A13: 1281884177 | B13: 1783002260.4899578
A14: 1281884177 | B14: 1783002265.8331609 | C14: -116 | D14: 5.75
A15: 3002419218 | B15: 1783002319.789969
A16: 3002419218 | B16: 1783002328.099039 | C16: -115 | D16: 7
A17: 1881288723 | B17: 1783002380.883848
A18: 1881288723 | B18: 1783002387.2552059 | C18: -113 | D18: 7.75
A19: 3691296788 | B19: 1783002441.1886022
A20: 3691296788 | B20: 1783002449.3946838 | C20: -114 | D20: 6
A21: 2849300501 | B21: 1.7830025e+09
A22: 2849300501 | B22: 1783002506.052993 | C22: -113 | D22: 6.5
A23: 3123426326 | B23: 1783002562.287217
A24: 3123426326 | B24: 1.7830026e+09 | C24: -113 | D24: 7.25
A25: 1000510487 | B25: 1783002620.6513479
A26: 1000510487 | B26: 1.7830026e+09 | C26: -113 | D26: 7
A27: 3512696856 | B27: 1783002680.5386581
A28: 3512696856 | B28: 1783002687.071434 | C28: -114 | D28: 6.75
A29: 776255513 | B29: 1783002739.893352
A30: 776255513 | B30: 1783002744.972497 | C30: -144 | D30: -20
A31: 2472154138 | B31: 1783002800.298692
A32: 2472154138 | B32: 1783002804.596437 | C32: -144 | D32: -20.25
A33: 2106106907 | B33: 1783002860.557227
A34: 2106106907 | B34: 1783002864.880573 | C34: -143 | D34: -19.25
A35: 87720988 | B35: 1783002920.772453
A36: 87720988 | B36: 1.7830029e+09 | C36: -113 | D36: 6.75
A37: 3391021085 | B37: 1783002980.338491
A38: 3876613150 | B38: 1783003041.804085
A39: 3876613150 | B39: 1783003048.557131 | C39: -114 | D39: 7.75
A40: 2840409119 | B40: 1783003102.7047732
...

Sheet 5sec_afternoon
A1: 2356606103 | B1: !6c73daa0 | C1: !dadfb8d4 | D1: 200 | E1: 2 | F1: 1 | G1: 1.7830163e+09 | H1: 1783016335.4551263 | I1: -139 | J1: -15.5 | K1: =H1-G1 -> 6.3738601
A2: 2917316760 | B2: !6c73daa0 | C2: !dadfb8d4 | D2: 200 | E2: 2 | F2: 2 | G2: 1.7830163e+09 | H2: 1783016356.7166433 | I2: -136 | J2: -12.75 | K2: =H2-G2 -> 22.52727
A3: 2939092121 | B3: !6c73daa0 | C3: !dadfb8d4 | D3: 200 | E3: 2 | F3: 3 | G3: 1.7830163e+09 | H3: 1783016347.4391334 | I3: -138 | J3: -13 | K3: =H3-G3 -> 8.1392901
A4: 4019089562 | B4: !6c73daa0 | C4: !dadfb8d4 | D4: 200 | E4: 2 | F4: 4 | G4: 1.7830163e+09 | H4: 1783016362.818397 | I4: -139 | J4: -13.75 | K4: =H4-G4 -> 18.40963
A5: 2159920284 | B5: !6c73daa0 | C5: !dadfb8d4 | D5: 200 | E5: 2 | F5: 6 | G5: 1.7830164e+09 | H5: 1.7830164e+09 | I5: -139 | J5: -15 | K5: =H5-G5 -> 17.58708
A6: 224053405 | B6: !6c73daa0 | C6: !dadfb8d4 | D6: 200 | E6: 2 | F6: 7 | G6: 1.7830164e+09 | H6: 1783016376.881785 | I6: -140 | J6: -16.25 | K6: =H6-G6 -> 17.14244
A7: 74218654 | B7: !6c73daa0 | C7: !dadfb8d4 | D7: 200 | E7: 2 | F7: 8 | G7: 1.7830164e+09 | H7: 1783016386.1462235 | I7: -138 | J7: -14.75 | K7: =H7-G7 -> 21.29572
A8: 498995359 | B8: !6c73daa0 | C8: !dadfb8d4 | D8: 200 | E8: 2 | F8: 9 | G8: 1.7830164e+09 | H8: 1783016397.048152 | I8: -138 | J8: -15.25 | K8: =H8-G8 -> 27.08927
A9: 3561841824 | B9: !6c73daa0 | C9: !dadfb8d4 | D9: 200 | E9: 2 | F9: 10 | G9: 1.7830164e+09 | H9: 1783016412.7418838 | I9: -139 | J9: -14.5 | K9: =H9-G9 -> 37.67363
A10: 2450951329 | B10: !6c73daa0 | C10: !dadfb8d4 | D10: 200 | E10: 2 | F10: 11 | G10: 1.7830164e+09 | H10: 1783016418.2682958 | I10: -138 | J10: -13.5 | K10: =H10-G10 -> 38.09231
A11: 1878023330 | B11: !6c73daa0 | C11: !dadfb8d4 | D11: 200 | E11: 2 | F11: 12 | G11: 1.7830164e+09 | H11: 1783016431.180133 | I11: -137 | J11: -12.5 | K11: =H11-G11 -> 45.89439
A12: 2770119843 | B12: !6c73daa0 | C12: !dadfb8d4 | D12: 200 | E12: 2 | F12: 13 | G12: 1.7830164e+09 | H12: 1783016443.2202673 | I12: -139 | J12: -16 | K12: =H12-G12 -> 52.82564
A13: 3487877285 | B13: !6c73daa0 | C13: !dadfb8d4 | D13: 200 | E13: 2 | F13: 15 | G13: 1.7830164e+09 | H13: 1783016456.2339046 | I13: -138 | J13: -12.75 | K13: =H13-G13 -> 55.62425
A14: 1769893030 | B14: !6c73daa0 | C14: !dadfb8d4 | D14: 200 | E14: 2 | F14: 16 | G14: 1.7830164e+09 | H14: 1783016450.3519466 | I14: -135 | J14: -11 | K14: =H14-G14 -> 44.63527
A15: 222209191 | B15: !6c73daa0 | C15: !dadfb8d4 | D15: 200 | E15: 2 | F15: 17 | G15: 1.7830164e+09 | H15: 1783016464.5338619 | I15: -135 | J15: -10.75 | K15: =H15-G15 -> 53.7113
A16: 1092912297 | B16: !6c73daa0 | C16: !dadfb8d4 | D16: 200 | E16: 2 | F16: 19 | G16: 1.7830164e+09 | H16: 1783016468.2182412 | I16: -136 | J16: -11.5 | K16: =H16-G16 -> 47.17824
A17: 252217514 | B17: !6c73daa0 | C17: !dadfb8d4 | D17: 200 | E17: 2 | F17: 20 | G17: 1.7830164e+09 | H17: 1783016507.583451 | I17: -138 | J17: -13 | K17: =H17-G17 -> 81.43657
... A39: 4230789320 | B39: !6c73daa0 | C39: !dadfb8d4 | D39: 200 | E39: 1 | F39: 50 | G39: 1.7830166e+09 | H39: 1783016583.8466175 | I39: -142 | J39: -16.5 | K39: =H39-G39 -> 4.4394

Sheet 5sec_afternoon_ACK
A1: 2356606103 | B1: 1783016332.580566
A2: 2356606103 | B2: 1783016340.221466 | C2: -115 | D2: 2.75
A3: 2939092121 | B3: 1783016345.122568
A4: 2939092121 | B4: 1783016352.493181 | C4: -116 | D4: 4
A5: 2917316760 | B5: 1783016355.001309
A6: 4019089562 | B6: 1783016358.6649458
A7: 2917316760 | B7: 1783016364.141789 | C7: -116 | D7: 6
A8: 2159920284 | B8: 1783016369.2181098
A9: 1839092891 | B9: 1.7830164e+09
A10: 224053405 | B10: 1783016374.7711942
A11: 224053405 | B11: 1783016380.6743119 | C11: -114 | D11: 5.25
A12: 74218654 | B12: 1783016383.883286
A13: 74218654 | B13: 1783016389.7930791 | C13: -116 | D13: 5.5
A14: 498995359 | B14: 1783016394.963625
A15: 498995359 | B15: 1783016400.379924 | C15: -117 | D15: 5.5
A16: 2450951329 | B16: 1783016425.761054 | C16: -116 | D16: 3.75
A17: 865043631 | B17: 1783016486.994307 | C17: -115 | D17: 4.75
A18: 267577520 | B18: 1783016491.822369 | C18: -116 | D18: 5.75
A19: 1092912297 | B19: 1783016493.389767 | C19: -116 | D19: 5.25
A20: 3421362347 | B20: 1783016503.972883 | C20: -116 | D20: 4.25
A21: 272061613 | B21: 1783016531.9712052 | C21: -117 | D21: 5
A22: 559829171 | B22: 1.7830166e+09 | C22: -144 | D22: -19.25
A23: 4230789320 | B23: 1783016583.569039

Sheet 20sec_afternon
A1: 1467316129 | B1: !6c73daa0 | C1: !dadfb8d4 | D1: 200 | E1: 2 | F1: 1 | G1: 1.7830178e+09 | H1: 1783017796.975007 | I1: -136 | J1: -12.25 | K1: =H1-G1 -> 6.3444698
A2: 1999121317 | B2: !6c73daa0 | C2: !dadfb8d4 | D2: 200 | E2: 2 | F2: 5 | G2: 1.7830179e+09 | H2: 1783017876.5711937 | I2: -138 | J2: -14 | K2: =H2-G2 -> 5.4751301
A3: 4272586662 | B3: !6c73daa0 | C3: !dadfb8d4 | D3: 200 | E3: 2 | F3: 6 | G3: 1.7830179e+09 | H3: 1783017897.7829523 | I3: -140 | J3: -14.5 | K3: =H3-G3 -> 6.57498
A4: 252475303 | B4: !6c73daa0 | C4: !dadfb8d4 | D4: 200 | E4: 2 | F4: 7 | G4: 1.7830179e+09 | H4: 1783017917.6423733 | I4: -135 | J4: -11.25 | K4: =H4-G4 -> 6.3227899
A5: 4172195752 | B5: !6c73daa0 | C5: !dadfb8d4 | D5: 200 | E5: 2 | F5: 8 | G5: 1.7830179e+09 | H5: 1783017939.1205282 | I5: -140 | J5: -16.25 | K5: =H5-G5 -> 7.6879401
A6: 1477650345 | B6: !6c73daa0 | C6: !dadfb8d4 | D6: 200 | E6: 2 | F6: 9 | G6: 1.783018e+09 | H6: 1783017957.1253686 | I6: -139 | J6: -13.5 | K6: =H6-G6 -> 5.5706301
A7: 2287170474 | B7: !6c73daa0 | C7: !dadfb8d4 | D7: 204 | E7: 1 | F7: 10 | G7: 1.783018e+09 | H7: 1783017975.7630978 | I7: -144 | J7: -19.75 | K7: =H7-G7 -> 4.0957599
A8: 2729804715 | B8: !6c73daa0 | C8: !dadfb8d4 | D8: 200 | E8: 2 | F8: 11 | G8: 1.783018e+09 | H8: 1783017997.8565435 | I8: -139 | J8: -15 | K8: =H8-G8 -> 6.0787499
A9: 3474316204 | B9: !6c73daa0 | C9: !dadfb8d4 | D9: 200 | E9: 2 | F9: 12 | G9: 1.783018e+09 | H9: 1783018018.542315 | I9: -143 | J9: -19 | K9: =H9-G9 -> 6.6559701
A10: 2904587181 | B10: !6c73daa0 | C10: !dadfb8d4 | D10: 200 | E10: 2 | F10: 13 | G10: 1.783018e+09 | H10: 1783018038.6994076 | I10: -139 | J10: -14.75 | K10: =H10-G10 -> 6.7007
A11: 1687119790 | B11: !6c73daa0 | C11: !dadfb8d4 | D11: 200 | E11: 2 | F11: 14 | G11: 1.7830181e+09 | H11: 1783018057.6879547 | I11: -138 | J11: -13 | K11: =H11-G11 -> 5.5768399
A12: 1779333039 | B12: !6c73daa0 | C12: !dadfb8d4 | D12: 200 | E12: 2 | F12: 15 | G12: 1.7830181e+09 | H12: 1783018079.5504515 | I12: -137 | J12: -13.25 | K12: =H12-G12 -> 7.3299
... A31: 2261360582 | B31: !6c73daa0 | C31: !dadfb8d4 | D31: 200 | E31: 2 | F31: 38 | G31: 1.7830185e+09 | H31: 1783018540.8111377 | I31: -138 | J31: -14 | K31: =H31-G31 -> 6.0650201
A32: 3107042247 | B32: !6c73daa0 | C32: !dadfb8d4 | D32: 200 | E32: 2 | F32: 39 | G32: 1.7830186e+09 | H32: 1.7830186e+09 | I32: -137 | J32: -13 | K32: =H32-G32 -> 6.4461
A33: 618178504 | B33: !6c73daa0 | C33: !dadfb8d4 | D33: 200 | E33: 2 | F33: 40 | G33: 1.7830186e+09 | H33: 1783018582.6741881 | I33: -136 | J33: -11.5 | K33: =H33-G33 -> 7.7019801
A34: 2577157065 | B34: !6c73daa0 | C34: !dadfb8d4 | D34: 200 | E34: 2 | F34: 41 | G34: 1.7830186e+09 | H34: 1783018601.5266757 | I34: -139 | J34: -14 | K34: =H34-G34 -> 6.44189
A35: 1685260234 | B35: !6c73daa0 | C35: !dadfb8d4 | D35: 200 | E35: 2 | F35: 42 | G35: 1.7830186e+09 | H35: 1783018622.0566795 | I35: -140 | J35: -15.25 | K35: =H35-G35 -> 6.85993
A36: 1037724619 | B36: !6c73daa0 | C36: !dadfb8d4 | D36: 200 | E36: 2 | F36: 43 | G36: 1.7830186e+09 | H36: 1783018641.3519313 | I36: -137 | J36: -14 | K36: =H36-G36 -> 6.0369298
A37: 3619554252 | B37: !6c73daa0 | C37: !dadfb8d4 | D37: 200 | E37: 2 | F37: 44 | G37: 1.7830187e+09 | H37: 1783018662.0478928 | I37: -137 | J37: -13 | K37: =H37-G37 -> 6.6208599
A38: 2948291533 | B38: !6c73daa0 | C38: !dadfb8d4 | D38: 200 | E38: 2 | F38: 45 | G38: 1.7830187e+09 | H38: 1783018681.4000723 | I38: -139 | J38: -13.75 | K38: =H38-G38 -> 5.8697701
A39: 265383886 | B39: !6c73daa0 | C39: !dadfb8d4 | D39: 200 | E39: 2 | F39: 46 | G39: 1.7830187e+09 | H39: 1783018701.0273178 | I39: -140 | J39: -15 | K39: =H39-G39 -> 5.39447
A40: 1526486991 | B40: !6c73daa0 | C40: !dadfb8d4 | D40: 200 | E40: 2 | F40: 47 | G40: 1.7830187e+09 | H40: 1783018722.2053673 | I40: -138 | J40: -13.75 | K40: =H40-G40 -> 6.4674299
A41: 1002842064 | B41: !6c73daa0 | C41: !dadfb8d4 | D41: 200 | E41: 2 | F41: 48 | G41: 1.7830187e+09 | H41: 1.7830187e+09 | I41: -139 | J41: -14 | K41: =H41-G41 -> 6.28808
A42: 2959909841 | B42: !6c73daa0 | C42: !dadfb8d4 | D42: 200 | E42: 2 | F42: 49 | G42: 1.7830188e+09 | H42: 1783018762.2660878 | I42: -137 | J42: -11.75 | K42: =H42-G42 -> 6.30755
A43: 139870162 | B43: !6c73daa0 | C43: !dadfb8d4 | D43: 200 | E43: 2 | F43: 50 | G43: 1.7830188e+09 | H43: 1783018783.9246407 | I43: -138 | J43: -13 | K43: =H43-G43 -> 7.8566899

Sheet 20sec_afternoon_ACK
A1: 3688657074 | B1: 1.7830178e+09 | C1: -116 | D1: 5.5
A2: 4230789320 | B2: 1783017790.8011389 | C2: -118 | D2: 5.5
A3: 1467316129 | B3: 1783017794.8938391
A4: 1467316129 | B4: 1783017801.410361 | C4: -118 | D4: 4.5
A5: 2273843106 | B5: 1783017814.167993
A6: 4060368803 | B6: 1783017834.991133
A7: 1543318436 | B7: 1783017853.9877481
A8: 1999121317 | B8: 1783017874.255117
A9: 1999121317 | B9: 1783017880.517596 | C9: -117 | D9: 6
A10: 4272586662 | B10: 1783017894.5197408
A11: 4272586662 | B11: 1783017902.655144 | C11: -115 | D11: 6.25
A12: 252475303 | B12: 1783017914.930089
A13: 252475303 | B13: 1783017919.719841 | C13: -144 | D13: -18.25
A14: 4172195752 | B14: 1783017935.6588411
A15: 4172195752 | B15: 1783017941.199511 | C15: -143 | D15: -18.25
A16: 1477650345 | B16: 1783017954.757159
A17: 1477650345 | B17: 1783017960.7351758 | C17: -115 | D17: 5.5
A18: 2287170474 | B18: 1783017981.571666 | C18: -121 | D18: 1.5
A19: 2729804715 | B19: 1783017996.103364
A20: 2729804715 | B20: 1783018001.253081 | C20: -115 | D20: 6.25
A21: 3474316204 | B21: 1783018015.903275
A22: 3474316204 | B22: 1783018021.853439 | C22: -116 | D22: 5.75
A23: 2904587181 | B23: 1783018035.942587
A24: 2904587181 | B24: 1783018042.379044 | C24: -117 | D24: 5.25
A25: 1687119790 | B25: 1783018056.0279949
A26: 1687119790 | B26: 1783018061.293341 | C26: -115 | D26: 6.25
A27: 1779333039 | B27: 1783018076.4704251
A28: 1779333039 | B28: 1783018084.375384 | C28: -117 | D28: 5.75
A29: 851579824 | B29: 1783018095.776905
A30: 851579824 | B30: 1783018102.1122859 | C30: -117 | D30: 4.75
A31: 994146225 | B31: 1783018115.969598
A32: 994146225 | B32: 1783018122.3329349 | C32: -116 | D32: 5.5
A33: 3343820722 | B33: 1783018136.627737
A34: 3343820722 | B34: 1.7830181e+09 | C34: -116 | D34: 5.5
A35: 3392257971 | B35: 1783018156.6316748
A36: 3392257971 | B36: 1783018163.007499 | C36: -115 | D36: 6
A37: 250540980 | B37: 1783018175.929143
A38: 250540980 | B38: 1783018182.064152 | C38: -114 | D38: 2.75
A39: 3071252405 | B39: 1.7830182e+09
A40: 3071252405 | B40: 1783018203.7090461 | C40: -115 | D40: 6
...

Sheet 40sec_afternoon
A1: 691916334 | B1: !6c73daa0 | C1: !dadfb8d4 | D1: 200 | E1: 2 | F1: 1 | G1: 1.78302e+09 | H1: 1783020009.1909359 | I1: -137 | J1: -12.5 | K1: =H1-G1 -> 6.5862
A2: 2797798959 | B2: !6c73daa0 | C2: !dadfb8d4 | D2: 200 | E2: 2 | F2: 2 | G2: 1.78302e+09 | H2: 1783020048.4355614 | I2: -139 | J2: -13.25 | K2: =H2-G2 -> 5.7166901
A3: 1026922032 | B3: !6c73daa0 | C3: !dadfb8d4 | D3: 200 | E3: 2 | F3: 3 | G3: 1.7830201e+09 | H3: 1783020089.5891953 | I3: -136 | J3: -11.5 | K3: =H3-G3 -> 6.7555101
A4: 2238286385 | B4: !6c73daa0 | C4: !dadfb8d4 | D4: 200 | E4: 2 | F4: 4 | G4: 1.7830201e+09 | H4: 1783020129.6820269 | I4: -137 | J4: -12.75 | K4: =H4-G4 -> 6.74176
A5: 3091546674 | B5: !6c73daa0 | C5: !dadfb8d4 | D5: 200 | E5: 2 | F5: 5 | G5: 1.7830202e+09 | H5: 1783020170.098229 | I5: -138 | J5: -12.5 | K5: =H5-G5 -> 7.0493002
A6: 1242593843 | B6: !6c73daa0 | C6: !dadfb8d4 | D6: 200 | E6: 2 | F6: 6 | G6: 1.7830202e+09 | H6: 1783020209.8095245 | I6: -139 | J6: -14.25 | K6: =H6-G6 -> 6.6500599
A7: 2466080308 | B7: !6c73daa0 | C7: !dadfb8d4 | D7: 200 | E7: 2 | F7: 7 | G7: 1.7830202e+09 | H7: 1783020250.4459383 | I7: -137 | J7: -13 | K7: =H7-G7 -> 7.1653099
A8: 1131968053 | B8: !6c73daa0 | C8: !dadfb8d4 | D8: 200 | E8: 2 | F8: 8 | G8: 1.7830203e+09 | H8: 1783020288.949084 | I8: -137 | J8: -12.25 | K8: =H8-G8 -> 5.5466001
A9: 2971797046 | B9: !6c73daa0 | C9: !dadfb8d4 | D9: 200 | E9: 2 | F9: 9 | G9: 1.7830203e+09 | H9: 1783020329.9410114 | I9: -141 | J9: -15.5 | K9: =H9-G9 -> 6.4207001
A10: 1492466231 | B10: !6c73daa0 | C10: !dadfb8d4 | D10: 200 | E10: 2 | F10: 10 | G10: 1.7830204e+09 | H10: 1783020369.1313133 | I10: -141 | J10: -16.5 | K10: =H10-G10 -> 5.49371
A11: 296775224 | B11: !6c73daa0 | C11: !dadfb8d4 | D11: 200 | E11: 2 | F11: 11 | G11: 1.7830204e+09 | H11: 1783020417.1983883 | I11: -136 | J11: -12 | K11: =H11-G11 -> 13.4401
A12: 2548022841 | B12: !6c73daa0 | C12: !dadfb8d4 | D12: 200 | E12: 2 | F12: 12 | G12: 1.7830204e+09 | H12: 1783020450.6309817 | I12: -138 | J12: -13.5 | K12: =H12-G12 -> 6.77514
... A16: 1610990143 | B16: !6c73daa0 | C16: !dadfb8d4 | D16: 200 | E16: 2 | F16: 18 | G16: 1.7830207e+09 | H16: 1783020689.8521705 | I16: -136 | J16: -11 | K16: =H16-G16 -> 5.3258801
A17: 2165583425 | B17: !6c73daa0 | C17: !dadfb8d4 | D17: 200 | E17: 2 | F17: 20 | G17: 1.7830208e+09 | H17: 1.7830208e+09 | I17: -138 | J17: -14 | K17: =H17-G17 -> 7.3111498
A18: 1337506370 | B18: !6c73daa0 | C18: !dadfb8d4 | D18: 200 | E18: 2 | F18: 21 | G18: 1.7830208e+09 | H18: 1783020810.7268763 | I18: -137 | J18: -13.25 | K18: =H18-G18 -> 5.8415601
A19: 810930755 | B19: !6c73daa0 | C19: !dadfb8d4 | D19: 200 | E19: 2 | F19: 22 | G19: 1.7830208e+09 | H19: 1783020850.3632212 | I19: -140 | J19: -15.25 | K19: =H19-G19 -> 5.3566699
A20: 1246384709 | B20: !6c73daa0 | C20: !dadfb8d4 | D20: 200 | E20: 2 | F20: 24 | G20: 1.7830209e+09 | H20: 1783020931.2313225 | I20: -140 | J20: -14.5 | K20: =H20-G20 -> 5.99031
A21: 3421019718 | B21: !6c73daa0 | C21: !dadfb8d4 | D21: 200 | E21: 2 | F21: 25 | G21: 1.783021e+09 | H21: 1783020970.971477 | I21: -141 | J21: -16.25 | K21: =H21-G21 -> 5.60783
A22: 3830065735 | B22: !6c73daa0 | C22: !dadfb8d4 | D22: 200 | E22: 2 | F22: 26 | G22: 1.783021e+09 | H22: 1783021010.1398838 | I22: -138 | J22: -12.75 | K22: =H22-G22 -> 4.66716
A23: 238068296 | B23: !6c73daa0 | C23: !dadfb8d4 | D23: 200 | E23: 2 | F23: 27 | G23: 1.783021e+09 | H23: 1783021051.1661298 | I23: -141 | J23: -16.25 | K23: =H23-G23 -> 5.5820801
A24: 3802525257 | B24: !6c73daa0 | C24: !dadfb8d4 | D24: 200 | E24: 2 | F24: 28 | G24: 1.7830211e+09 | H24: 1783021092.2036004 | I24: -139 | J24: -15.5 | K24: =H24-G24 -> 6.5044
A25: 3747206730 | B25: !6c73daa0 | C25: !dadfb8d4 | D25: 200 | E25: 2 | F25: 29 | G25: 1.7830211e+09 | H25: 1783021132.334375 | I25: -140 | J25: -16 | K25: =H25-G25 -> 6.5158298
A26: 1543323211 | B26: !6c73daa0 | C26: !dadfb8d4 | D26: 200 | E26: 2 | F26: 30 | G26: 1.7830212e+09 | H26: 1783021171.6324637 | I26: -140 | J26: -14.75 | K26: =H26-G26 -> 5.6925702
A27: 1945340492 | B27: !6c73daa0 | C27: !dadfb8d4 | D27: 200 | E27: 2 | F27: 31 | G27: 1.7830212e+09 | H27: 1783021213.1885583 | I27: -138 | J27: -13.75 | K27: =H27-G27 -> 7.12658
A28: 459481677 | B28: !6c73daa0 | C28: !dadfb8d4 | D28: 200 | E28: 2 | F28: 32 | G28: 1.7830212e+09 | H28: 1783021251.7899742 | I28: -139 | J28: -14.5 | K28: =H28-G28 -> 5.6156399
A29: 1286458958 | B29: !6c73daa0 | C29: !dadfb8d4 | D29: 200 | E29: 2 | F29: 33 | G29: 1.7830213e+09 | H29: 1783021292.2302663 | I29: -140 | J29: -15.5 | K29: =H29-G29 -> 5.9374399
... A46: 2176688735 | B46: !6c73daa0 | C46: !dadfb8d4 | D46: 200 | E46: 2 | F46: 50 | G46: 1.783022e+09 | H46: 1783021973.9129288 | I46: -139 | J46: -14.25 | K46: =H46-G46 -> 5.61251

Sheet 40sec_afternoon_ACK
A1: 691916334 | B1: 1783020006.617313
A2: 691916334 | B2: 1783020012.536299 | C2: -115 | D2: 5.75
A3: 2797798959 | B3: 1783020045.487129
A4: 2797798959 | B4: 1783020050.403436 | C4: -145 | D4: -20.75
A5: 1026922032 | B5: 1783020086.353353
A6: 1026922032 | B6: 1783020093.383292 | C6: -116 | D6: 5.5
A7: 2238286385 | B7: 1783020126.635094
A8: 2238286385 | B8: 1783020136.347266 | C8: -115 | D8: 5.5
A9: 3091546674 | B9: 1783020167.3358872
A10: 3091546674 | B10: 1783020174.0981991 | C10: -116 | D10: 5.75
A11: 1242593843 | B11: 1783020207.247263
A12: 1242593843 | B12: 1783020213.6835158 | C12: -116 | D12: 5.5
A13: 2466080308 | B13: 1783020247.138649
A14: 2466080308 | B14: 1783020254.2938938 | C14: -115 | D14: 5.5
A15: 1131968053 | B15: 1783020287.167048
A16: 1131968053 | B16: 1783020291.165178 | C16: -145 | D16: -19.5
A17: 2971797046 | B17: 1783020326.7043772
A18: 2971797046 | B18: 1783020333.6799302 | C18: -115 | D18: 5.75
A19: 1492466231 | B19: 1783020366.256931
A20: 1492466231 | B20: 1783020372.294511 | C20: -116 | D20: 6
A21: 296775224 | B21: 1783020415.246271
A22: 296775224 | B22: 1783020420.423418 | C22: -114 | D22: 7.75
A23: 2548022841 | B23: 1783020447.2505379
A24: 2548022841 | B24: 1783020454.975438 | C24: -114 | D24: 6.25
A25: 1000615482 | B25: 1783020487.456285
A26: 1000615482 | B26: 1783020494.088054 | C26: -116 | D26: 5.75
A27: 3502227003 | B27: 1783020535.735747
A28: 246421052 | B28: 1783020574.603737
A29: 185778749 | B29: 1783020607.5205371
A30: 2781242942 | B30: 1783020648.6109052
A31: 2781242942 | B31: 1783020654.189574 | C31: -115 | D31: 7.25
A32: 1610990143 | B32: 1783020687.907444
A33: 1610990143 | B33: 1783020693.847768 | C33: -115 | D33: 6
A34: 2074893888 | B34: 1783020728.2282119
A35: 2165583425 | B35: 1783020768.6440651
A36: 2165583425 | B36: 1783020775.633368 | C36: -114 | D36: 7.5
A37: 1337506370 | B37: 1783020807.583245
A38: 1337506370 | B38: 1783020814.590511 | C38: -116 | D38: 5.5
A39: 810930755 | B39: 1783020847.973183
A40: 810930755 | B40: 1783020854.4282088 | C40: -115 | D40: 5.25
...

Sheet 1min_afternoon
A1: 3809386175 | B1: !6c73daa0 | C1: !dadfb8d4 | D1: 200 | E1: 2 | F1: 1 | G1: 1.7830232e+09 | H1: 1783023220.294314 | I1: -138 | J1: -14 | K1: =H1-G1 -> 5.6308901
A2: 247190208 | B2: !6c73daa0 | C2: !dadfb8d4 | D2: 200 | E2: 2 | F2: 2 | G2: 1.7830233e+09 | H2: 1783023281.2951837 | I2: -137 | J2: -11.5 | K2: =H2-G2 -> 6.56829
A3: 3852823234 | B3: !6c73daa0 | C3: !dadfb8d4 | D3: 200 | E3: 2 | F3: 4 | G3: 1.7830234e+09 | H3: 1783023401.4463255 | I3: -135 | J3: -11.25 | K3: =H3-G3 -> 6.4806402
A4: 177872579 | B4: !6c73daa0 | C4: !dadfb8d4 | D4: 200 | E4: 2 | F4: 5 | G4: 1.7830235e+09 | H4: 1783023460.720505 | I4: -137 | J4: -13.25 | K4: =H4-G4 -> 5.63363
A5: 3330440900 | B5: !6c73daa0 | C5: !dadfb8d4 | D5: 200 | E5: 2 | F5: 6 | G5: 1.7830235e+09 | H5: 1783023522.363445 | I5: -138 | J5: -14 | K5: =H5-G5 -> 7.1609299
A6: 2838615749 | B6: !6c73daa0 | C6: !dadfb8d4 | D6: 200 | E6: 2 | F6: 7 | G6: 1.7830236e+09 | H6: 1783023581.8370068 | I6: -138 | J6: -12.5 | K6: =H6-G6 -> 6.5139899
A7: 3111710406 | B7: !6c73daa0 | C7: !dadfb8d4 | D7: 200 | E7: 2 | F7: 8 | G7: 1.7830236e+09 | H7: 1783023641.5861545 | I7: -140 | J7: -14.75 | K7: =H7-G7 -> 6.1415
A8: 769615559 | B8: !6c73daa0 | C8: !dadfb8d4 | D8: 200 | E8: 2 | F8: 9 | G8: 1.7830237e+09 | H8: 1783023700.9054506 | I8: -137 | J8: -12 | K8: =H8-G8 -> 5.3382502
A9: 2564463304 | B9: !6c73daa0 | C9: !dadfb8d4 | D9: 200 | E9: 2 | F9: 10 | G9: 1.7830238e+09 | H9: 1783023762.3203762 | I9: -138 | J9: -13.25 | K9: =H9-G9 -> 6.6258399
A10: 3326313161 | B10: !6c73daa0 | C10: !dadfb8d4 | D10: 200 | E10: 2 | F10: 11 | G10: 1.7830238e+09 | H10: 1783023821.043258 | I10: -136 | J10: -11.75 | K10: =H10-G10 -> 5.23629
A11: 2360782538 | B11: !6c73daa0 | C11: !dadfb8d4 | D11: 200 | E11: 2 | F11: 12 | G11: 1.7830239e+09 | H11: 1783023881.9785447 | I11: -139 | J11: -13.75 | K11: =H11-G11 -> 6.07002
A12: 3521305291 | B12: !6c73daa0 | C12: !dadfb8d4 | D12: 200 | E12: 2 | F12: 13 | G12: 1.7830239e+09 | H12: 1783023941.1530247 | I12: -138 | J12: -13.25 | K12: =H12-G12 -> 5.128
... A49: 2203009776 | B49: !6c73daa0 | C49: !dadfb8d4 | D49: 200 | E49: 2 | F49: 50 | G49: 1.7830262e+09 | H49: 1783026166.9951782 | I49: -137 | J49: -12 | K49: =H49-G49 -> 6.7509301

Sheet 1min_afternoon_ACK
A1: 3809386175 | B1: 1783023218.0770612
A2: 3809386175 | B2: 1783023222.555608 | C2: -144 | D2: -18.75
A3: 247190208 | B3: 1783023278.224046
A4: 247190208 | B4: 1783023283.585782 | C4: -141 | D4: -17.25
A5: 3785662145 | B5: 1783023337.960906
A6: 3852823234 | B6: 1783023399.084385
A7: 3852823234 | B7: 1783023403.5687401 | C7: -144 | D7: -18.5
A8: 177872579 | B8: 1783023458.342535
A9: 177872579 | B9: 1783023464.338372 | C9: -114 | D9: 7.25
A10: 3330440900 | B10: 1.7830235e+09
A11: 3330440900 | B11: 1783023525.410027 | C11: -115 | D11: 5.75
A12: 2838615749 | B12: 1783023579.078827
A13: 2838615749 | B13: 1783023585.401082 | C13: -115 | D13: 5.5
A14: 3111710406 | B14: 1783023639.428298
A15: 3111710406 | B15: 1783023643.669145 | C15: -143 | D15: -17.5
A16: 769615559 | B16: 1783023698.824466
A17: 769615559 | B17: 1783023704.440625 | C17: -115 | D17: 6.5
A18: 2564463304 | B18: 1783023760.074839
A19: 2564463304 | B19: 1783023767.118054 | C19: -114 | D19: 7.5
A20: 3326313161 | B20: 1783023818.806252
A21: 3326313161 | B21: 1783023824.467944 | C21: -114 | D21: 6.5
A22: 2360782538 | B22: 1783023879.873667
A23: 2360782538 | B23: 1.7830239e+09 | C23: -144 | D23: -19
A24: 3521305291 | B24: 1783023939.2968059
A25: 3521305291 | B25: 1783023944.6199849 | C25: -116 | D25: 6
A26: 633026252 | B26: 1783023999.403658
A27: 633026252 | B27: 1783024004.986145 | C27: -114 | D27: 6.5
A28: 144538317 | B28: 1783024059.003235
A29: 144538317 | B29: 1783024066.0825238 | C29: -114 | D29: 7
A30: 3512083150 | B30: 1783024120.595226
A31: 3512083150 | B31: 1783024126.135933 | C31: -143 | D31: -19
A32: 693467855 | B32: 1783024179.599832
A33: 693467855 | B33: 1783024185.105421 | C33: -115 | D33: 7.25
A34: 2015946448 | B34: 1783024240.118091
A35: 2015946448 | B35: 1.7830242e+09 | C35: -116 | D35: 6
A36: 1443236561 | B36: 1783024301.2874591
A37: 1443236561 | B37: 1783024308.656608 | C37: -114 | D37: 6.25
A38: 97265362 | B38: 1783024360.586373
A39: 97265362 | B39: 1783024365.090655 | C39: -145 | D39: -19.5
A40: 2322624211 | B40: 1783024420.305384
...

Sheet total
A1: MORNING | B1: 5sec | C1: 20sec | D1: 40sec | E1: 1min | F1: total
A2: DR (%) | B2: =COUNT('5sec_morning'!E2:E38)/50*100 -> 74 | C2: =COUNT('20sec_morning'!E2:E50)/50*100 -> 98 | D2: =COUNT('40sec_morning'!E2:E51)/50*100 -> 100 | E2: =COUNT('1min_morning'!E2:E51)/50*100 -> 100 | F2: =(32+49+50+50)/200*100 -> 90.5
A3: latency | B3: N/A | C3: N/A | D3: N/A | E3: N/A | F3: 0
A4: avg hops | B4: =AVERAGE('5sec_morning'!E2:E38) -> 1.972973 | C4: =AVERAGE('20sec_morning'!E2:E50) -> 1.9591837 | D4: =AVERAGE('40sec_morning'!E2:E51) -> 2 | E4: =AVERAGE('1min_morning'!E2:E51) -> 1.96 | F4: =AVERAGE(B4:E4) -> 1.9730392
A5: avg RSSI (outgoing) | B5: =AVERAGE('5sec_morning'!H2:H38) -> -137.64865 | C5: =AVERAGE('20sec_morning'!H2:H50) -> -138.77551 | D5: =AVERAGE('40sec_morning'!H2:H51) -> -138.84 | E5: =AVERAGE('1min_morning'!H2:H51) -> -139.12 | F5: =AVERAGE(B5:E5) -> -138.59604
A6: RSSI SD (outgoing) | B6: =_xlfn.STDEV.S('5sec_morning'!H2:H38) -> 1.9034503 | C6: =_xlfn.STDEV.S('20sec_morning'!H2:H50) -> 1.7708909 | D6: =_xlfn.STDEV.S('40sec_morning'!H2:H51) -> 1.3606721 | E6: =_xlfn.STDEV.S('1min_morning'!H2:H51) -> 5.5019106 | F6: =AVERAGE(B6:E6) -> 2.634231
A7: avg SNR (outgoing) | B7: =AVERAGE('5sec_morning'!I2:I38) -> -12.797297 | C7: =AVERAGE('20sec_morning'!I2:I50) -> -13.897959 | D7: =AVERAGE('40sec_morning'!I2:I51) -> -14.09 | E7: =AVERAGE('1min_morning'!I2:I51) -> -14.57 | F7: =AVERAGE(B7:E7) -> -13.838814
A8: SNR SD (outgoing) | B8: =_xlfn.STDEV.S('5sec_morning'!I2:I38) -> 1.7448713 | C8: =_xlfn.STDEV.S('20sec_morning'!I2:I50) -> 1.5180497 | D8: =_xlfn.STDEV.S('40sec_morning'!I2:I51) -> 1.1074424 | E8: =_xlfn.STDEV.S('1min_morning'!I2:I51) -> 3.7437158 | F8: =AVERAGE(B8:E8) -> 2.0285198
A9: ACKs received | B9: {=SUMPRODUCT(--(COUNTIF('5sec_morning_ACK'!A2:A19, '5sec_morning'!A2:A38)>0))} -> 13 | C9: {=SUMPRODUCT(--(COUNTIF('20sec_morning_ACK'!A2:A102, '20sec_morning'!A2:A50)>0))} -> 49 | D9: {=SUMPRODUCT(--(COUNTIF('40sec_morning_ACK'!A2:A101, '40sec_morning'!A2:A51)>0))} -> 50 | E9: {=SUMPRODUCT(--(COUNTIF('1min_morning_ACK'!A1:A98, '1min_morning'!A2:A51)>0))} -> 50 | F9: =SUM(B9:E9) -> 162
A10: ACKs received (%) | B10: =B9/50*100 -> 26 | C10: =C9/50*100 -> 98 | D10: =D9/50*100 -> 100 | E10: =E9/50*100 -> 100 | F10: =F9/200*100 -> 81
A11: avg RSSI (ACK) | B11: =AVERAGE('5sec_morning_ACK'!C:C) -> -119.3 | C11: =AVERAGE('20sec_morning_ACK'!C:C) -> -121.35294 | D11: =AVERAGE('40sec_morning_ACK'!C:C) -> -124.62 | E11: =AVERAGE('1min_morning_ACK'!C:C) -> -122.52083 | F11: =AVERAGE(B11:E11) -> -121.94844
A12: RSSI SD (ACK) | B12: =_xlfn.STDEV.S('5sec_morning_ACK'!C:C) -> 13.055863 | C12: =_xlfn.STDEV.S('20sec_morning_ACK'!C:C) -> 11.172866 | D12: =_xlfn.STDEV.S('40sec_morning_ACK'!C:C) -> 14.515143 | E12: =_xlfn.STDEV.S('1min_morning_ACK'!C:C) -> 15.182562 | F12: =AVERAGE(B12:E12) -> 13.481609
A13: avg SNR (ACK) | B13: =AVERAGE('5sec_morning_ACK'!D:D) -> 1.675 | C13: =AVERAGE('20sec_morning_ACK'!D:D) -> 0.44607843 | D13: =AVERAGE('40sec_morning_ACK'!D:D) -> -2.45 | E13: =AVERAGE('1min_morning_ACK'!D:D) -> -1.1197917 | F13: =AVERAGE(B13:E13) -> -0.36217831
A14: SNR SD (ACK) | B14: =_xlfn.STDEV.S('5sec_morning_ACK'!D8:D19) -> 9.0569188 | C14: =_xlfn.STDEV.S('20sec_morning_ACK'!D:D) -> 9.9889081 | D14: =_xlfn.STDEV.S('40sec_morning_ACK'!D:D) -> 12.918801 | E14: =_xlfn.STDEV.S('1min_morning_ACK'!D:D) -> 12.50319 | F14: =AVERAGE(B14:E14) -> 11.116954
A16: AFTERNOON | B16: 5sec | C16: 20sec | D16: 40sec | E16: 1min | F16: total
A17: DR (%) | B17: =COUNT('5sec_afternoon'!D1:D39)/50*100 -> 78 | C17: =COUNT('20sec_afternon'!D1:D43)/50*100 -> 86 | D17: =COUNT('40sec_afternoon'!D2:D46)/50*100 -> 90 | E17: =COUNT('1min_afternoon'!E1:E49)/50*100 -> 98 | F17: =COUNT('5sec_afternoon'!F:F,'20sec_afternon'!F:F,'40sec_afternoon'!F:F,'1min_afternoon'!F:F)/200*100 -> 88.5
A18: latency | B18: =AVERAGE('5sec_afternoon'!K1:K39) -> 65.99181 | C18: =AVERAGE('20sec_afternon'!K1:K43) -> 6.236659 | D18: =AVERAGE('40sec_afternoon'!K:K) -> 6.6167393 | E18: =AVERAGE('1min_afternoon'!K:K) -> 6.2146382 | F18: =AVERAGE(C18:E18) -> 6.3560122 | G18: =AVERAGE(B18:E18) -> 21.264962
A19: latency SD | B19: =_xlfn.STDEV.S('5sec_afternoon'!K:K) -> 44.09888 | C19: =_xlfn.STDEV.S('20sec_afternon'!K:K) -> 0.81603368 | D19: =_xlfn.STDEV.S('40sec_afternoon'!K:K) -> 1.7500642 | E19: =_xlfn.STDEV.S('1min_afternoon'!K:K) -> 0.84907817 | F19: =_xlfn.STDEV.S('20sec_afternon'!K:K,'40sec_afternoon'!K:K,'1min_afternoon'!K:K) -> 1.2235958 | G19: =_xlfn.STDEV.S('5sec_afternoon'!K:K,'20sec_afternon'!K:K,'40sec_afternoon'!K:K,'1min_afternoon'!K:K) -> 32.178957
A20: avg hops | B20: =AVERAGE('5sec_afternoon'!E1:E39) -> 1.8974359 | C20: =AVERAGE('20sec_afternon'!E:E) -> 1.9767442 | D20: =AVERAGE('40sec_afternoon'!E:E) -> 1.9565217 | E20: =AVERAGE('1min_afternoon'!E:E) -> 2 | F20: =AVERAGE(B20:E20) -> 1.9576755
A21: avg RSSI (outgoing) | B21: =AVERAGE('5sec_afternoon'!I:I) -> -138.17949 | C21: =AVERAGE('20sec_afternon'!I:I) -> -138.60465 | D21: =AVERAGE('40sec_afternoon'!I:I) -> -138.8913 | E21: =AVERAGE('1min_afternoon'!I:I) -> -137.4898 | F21: =AVERAGE(B21:E21) -> -138.29131
A22: RSSI SD (outgoing) | B22: =_xlfn.STDEV.S('5sec_afternoon'!I:I) -> 1.7602601 | C22: =_xlfn.STDEV.S('20sec_afternon'!I:I) -> 1.7746835 | D22: =_xlfn.STDEV.S('40sec_afternoon'!I:I) -> 2.1932043 | E22: =_xlfn.STDEV.S('1min_afternoon'!I:I) -> 1.2097253 | F22: =_xlfn.STDEV.S('5sec_afternoon'!I:I,'20sec_afternon'!I:I,'40sec_afternoon'!I:I,'1min_afternoon'!I:I) -> 1.8300444
A23: avg SNR (outgoing) | B23: =AVERAGE('5sec_afternoon'!J:J) -> -14.121795 | C23: =AVERAGE('20sec_afternon'!J:J) -> -13.976744 | D23: =AVERAGE('40sec_afternoon'!J:J) -> -14.440217 | E23: =AVERAGE('1min_afternoon'!J:J) -> -12.877551 | F23: =AVERAGE(B23:E23) -> -13.854077
A24: SNR SD (outgoing) | B24: =_xlfn.STDEV.S('5sec_afternoon'!J:J) -> 1.7022352 | C24: =_xlfn.STDEV.S('20sec_afternon'!J:J) -> 1.6768859 | D24: =_xlfn.STDEV.S('40sec_afternoon'!J:J) -> 2.0576313 | E24: =_xlfn.STDEV.S('1min_afternoon'!J:J) -> 1.1604624 | F24: =_xlfn.STDEV.S('5sec_afternoon'!J:J,'20sec_afternon'!J:J,'40sec_afternoon'!J:J,'1min_afternoon'!J:J) -> 1.7664738
A25: ACKs received | B25: {=SUMPRODUCT(--(COUNTIF(allACK!A:A,'5sec_afternoon'!A:A)>0))} -> 17 | C25: {=SUMPRODUCT(--(COUNTIF(allACK!A:A,'20sec_afternon'!A:A)>0))} -> 43 | D25: {=SUMPRODUCT(--(COUNTIF(allACK!A:A,'40sec_afternoon'!A:A)>0))} -> 46 | E25: {=SUMPRODUCT(--(COUNTIF(allACK!A:A,'1min_afternoon'!A:A)>0))} -> 49 | F25: =SUM(B25:E25) -> 155
A26: ACKs received (%) | B26: =B25/50*100 -> 34 | C26: =C25/50*100 -> 86 | D26: =D25/50*100 -> 92 | E26: =E25/50*100 -> 98 | F26: =F25/200*100 -> 77.5
A27: avg RSSI (ACK) | B27: =AVERAGE('5sec_afternoon_ACK'!C:C) -> -118 | C27: =AVERAGE('20sec_afternoon_ACK'!C:C) -> -121.37209 | D27: =AVERAGE('40sec_afternoon_ACK'!C:C) -> -118.77778 | E27: =AVERAGE('1min_afternoon_ACK'!C:C) -> -120.7551 | F27: =AVERAGE('5sec_afternoon_ACK'!C:C,'20sec_afternoon_ACK'!C:C,'40sec_afternoon_ACK'!C:C,'1min_afternoon_ACK'!C:C) -> -120.1
A28: RSSI SD (ACK) | B28: =_xlfn.STDEV.S('5sec_afternoon_ACK'!C:C) -> 7.8528127 | C28: =_xlfn.STDEV.S('20sec_afternoon_ACK'!C:C) -> 10.987056 | D28: =_xlfn.STDEV.S('40sec_afternoon_ACK'!C:C) -> 10.321841 | E28: =_xlfn.STDEV.S('1min_afternoon_ACK'!C:C) -> 11.728758 | F28: =_xlfn.STDEV.S('5sec_afternoon_ACK'!C:C,'20sec_afternoon_ACK'!C:C,'40sec_afternoon_ACK'!C:C,'1min_afternoon_ACK'!C:C) -> 10.783874
A29: avg SNR (ACK) | B29: =AVERAGE('5sec_afternoon_ACK'!D:D) -> 2.9615385 | C29: =AVERAGE('20sec_afternoon_ACK'!D:D) -> 0.98837209 | D29: =AVERAGE('40sec_afternoon_ACK'!D:D) -> 2.7777778 | E29: =AVERAGE('1min_afternoon_ACK'!D:D) -> 1.1071429 | F29: =AVERAGE('5sec_afternoon_ACK'!D:D,'20sec_afternoon_ACK'!D:D,'40sec_afternoon_ACK'!D:D,'1min_afternoon_ACK'!D:D) -> 1.735
A30: SNR SD (ACK) | B30: =_xlfn.STDEV.S('5sec_afternoon_ACK'!D:D) -> 6.7359778 | C30: =_xlfn.STDEV.S('20sec_afternoon_ACK'!D:D) -> 9.5090736 | D30: =_xlfn.STDEV.S('40sec_afternoon_ACK'!D:D) -> 8.9338195 | E30: =_xlfn.STDEV.S('1min_afternoon_ACK'!D:D) -> 10.25254 | F30: =_xlfn.STDEV.S('5sec_afternoon_ACK'!D:D,'20sec_afternoon_ACK'!D:D,'40sec_afternoon_ACK'!D:D,'1min_afternoon_ACK'!D:D) -> 9.3447321

Sheet allACK
A1: ALL ACK PACKET NUMBERS
A2: 2356606103
A3: 2939092121
A4: 2917316760
A5: 4019089562
A6: 2159920284
A7: 1839092891
A8: 224053405
A9: 74218654
A10: 498995359
A11: 2450951329
A12: 865043631
A13: 267577520
... A169: 2203009776
