Workbook

Sheet dynamic_test_3hop
A1: localID | B1: packetID | C1: nodeID | D1: sendTime | E1: receivedTime | F1: latency | G1: rssi | H1: snr | I1: lat | J1: long | K1: alt | L1: hopStart | M1: hopLimit | N1: hopsUsed | O1: delivery rate (%)
A2: 1 | B2: 2633666616 | C2: !dadfb03c | D2: 1783607744.8772821 | E2: 1783607747.1792386 | F2: =E2-D2 -> 2.30195 | G2: -39 | H2: 7.75 | I2: 44.637543 | J2: -63.587178 | K2: 48 | L2: 3 | M2: 3 | N2: =L2-M2 -> 0 | O2: =COUNT(A2:A27)/A27*100 -> 50
A3: 2 | B3: 3477515321 | C3: !dadfb03c | D3: 1783607774.996068 | E3: 1783607777.1019025 | F3: =E3-D3 -> 2.1058402 | G3: -51 | H3: 7.5 | I3: 44.637543 | J3: -63.587178 | K3: 48 | L3: 3 | M3: 3 | N3: =L3-M3 -> 0
A4: 3 | B4: 2254213178 | C4: !dadfb03c | D4: 1783607805.116203 | E4: 1783607807.083689 | F4: =E4-D4 -> 1.9674799 | G4: -43 | H4: 7.5 | I4: 44.637543 | J4: -63.587178 | K4: 48 | L4: 3 | M4: 3 | N4: =L4-M4 -> 0
A5: 5 | B5: 855942204 | C5: !dadfb03c | D5: 1783607865.351221 | E5: 1783607867.265962 | F5: =E5-D5 -> 1.9147401 | G5: -110 | H5: -0.5 | I5: 44.63756 | J5: -63.587568 | K5: 50 | L5: 3 | M5: 3 | N5: =L5-M5 -> 0
A6: 6 | B6: 308669501 | C6: !dadfb03c | D6: 1783607895.464409 | E6: 1783607900.216167 | F6: =E6-D6 -> 4.75176 | G6: -78 | H6: 9.25 | I6: 44.63713 | J6: -63.587627 | K6: 48 | L6: 3 | M6: 2 | N6: =L6-M6 -> 1
A7: 10 | B7: 2674245697 | C7: !dadfb03c | D7: 1783608015.924809 | E7: 1783608020.124709 | F7: =E7-D7 -> 4.1999002 | G7: -78 | H7: 9 | I7: 44.635899 | J7: -63.587878 | K7: 46 | L7: 3 | M7: 2 | N7: =L7-M7 -> 1
A8: 13 | B8: 1213493316 | C8: !dadfb03c | D8: 1783608106.2908878 | E8: 1783608113.5910997 | F8: =E8-D8 -> 7.30021 | G8: -80 | H8: 8.75 | I8: 44.635615 | J8: -63.589516 | K8: 49 | L8: 3 | M8: 1 | N8: =L8-M8 -> 2
A9: 18 | B9: 775394377 | C9: !dadfb03c | D9: 1783608256.9066129 | E9: 1783608265.131039 | F9: =E9-D9 -> 8.2244201 | G9: -80 | H9: 7.75 | I9: 44.634939 | J9: -63.592325 | K9: 44 | L9: 3 | N9: =L9-M9 -> 3
A10: 27 | B10: 2458402898 | C10: !dadfb03c | D10: 1783608528.0274801 | E10: 1783608535.955114 | F10: =E10-D10 -> 7.9276302 | G10: -78 | H10: 8.75 | I10: 44.636687 | J10: -63.594874 | K10: 46 | L10: 3 | N10: =L10-M10 -> 3
A11: 31 | B11: 2914107478 | C11: !dadfb03c | D11: 1783608648.514365 | E11: 1783608657.2877207 | F11: =E11-D11 -> 8.77336 | G11: -84 | H11: 8.75 | I11: 44.636906 | J11: -63.593182 | K11: 53 | L11: 3 | N11: =L11-M11 -> 3
A12: 32 | B12: 3886922839 | C12: !dadfb03c | D12: 1783608678.640099 | E12: 1783608685.6454601 | F12: =E12-D12 -> 7.0053699 | G12: -81 | H12: 8.5 | I12: 44.636679 | J12: -63.592816 | K12: 52 | L12: 3 | M12: 1 | N12: =L12-M12 -> 2
A13: 33 | B13: 1128078424 | C13: !dadfb03c | D13: 1783608708.768106 | E13: 1783608712.8818574 | F13: =E13-D13 -> 4.11375 | G13: -80 | H13: 9 | I13: 44.636278 | J13: -63.592574 | K13: 52 | L13: 3 | M13: 2 | N13: =L13-M13 -> 1
A14: 34 | B14: 3675344985 | C14: !dadfb03c | D14: 1783608738.896904 | E14: 1783608743.2310798 | F14: =E14-D14 -> 4.3341701 | G14: -79 | H14: 8.75 | I14: 44.636584 | J14: -63.592254 | K14: 51 | L14: 3 | M14: 2 | N14: =L14-M14 -> 1
A15: 36 | B15: 2969691 | C15: !dadfb03c | D15: 1783608799.151428 | E15: 1783608802.8935812 | F15: =E15-D15 -> 3.7421598 | G15: -79 | H15: 9.75 | I15: 44.636744 | J15: -63.591111 | K15: 50 | L15: 3 | M15: 2 | N15: =L15-M15 -> 1
A16: 38 | B16: 1666175069 | C16: !dadfb03c | D16: 1783608859.406923 | E16: 1783608869.445931 | F16: =E16-D16 -> 10.03901 | G16: -79 | H16: 9.25 | I16: 44.637351 | J16: -63.590374 | K16: 54 | L16: 3 | M16: 1 | N16: =L16-M16 -> 2
A17: 39 | B17: 1819711582 | C17: !dadfb03c | D17: 1783608889.534632 | E17: 1783608896.2272413 | F17: =E17-D17 -> 6.69261 | G17: -80 | H17: 7.75 | I17: 44.63772 | J17: -63.590268 | K17: 55 | L17: 3 | M17: 1 | N17: =L17-M17 -> 2
A18: 41 | B18: 2244295776 | C18: !dadfb03c | D18: 1783608949.779661 | E18: 1783608953.607958 | F18: =E18-D18 -> 3.82829 | G18: -81 | H18: 8.75 | I18: 44.638552 | J18: -63.59076 | K18: 56 | L18: 3 | M18: 2 | N18: =L18-M18 -> 1
A19: 43 | B19: 876472418 | C19: !dadfb03c | D19: 1783609010.028699 | E19: 1783609019.4571238 | F19: =E19-D19 -> 9.4284298 | G19: -81 | H19: 8.75 | I19: 44.639318 | J19: -63.590517 | K19: 57 | L19: 3 | N19: =L19-M19 -> 3
A20: 44 | B20: 2327524451 | C20: !dadfb03c | D20: 1783609040.147904 | E20: 1783609048.4374907 | F20: =E20-D20 -> 8.2895899 | G20: -79 | H20: 9.25 | I20: 44.639173 | J20: -63.58997 | K20: 58 | L20: 3 | M20: 1 | N20: =L20-M20 -> 2
A21: 45 | B21: 847907940 | C21: !dadfb03c | D21: 1783609070.272023 | E21: 1783609074.4896786 | F21: =E21-D21 -> 4.2176499 | G21: -81 | H21: 9 | I21: 44.6388 | J21: -63.589725 | K21: 57 | L21: 3 | M21: 2 | N21: =L21-M21 -> 1
A22: 47 | B22: 2635497574 | C22: !dadfb03c | D22: 1783609130.5294101 | E22: 1783609134.5983536 | F22: =E22-D22 -> 4.0689402 | G22: -81 | H22: 8 | I22: 44.638023 | J22: -63.589286 | K22: 55 | L22: 3 | M22: 2 | N22: =L22-M22 -> 1
A23: 48 | B23: 2951375975 | C23: !dadfb03c | D23: 1783609160.654915 | E23: 1783609164.9157374 | F23: =E23-D23 -> 4.2608199 | G23: -78 | H23: 9.75 | I23: 44.637579 | J23: -63.589177 | K23: 54 | L23: 3 | M23: 2 | N23: =L23-M23 -> 1
A24: 49 | B24: 4144805992 | C24: !dadfb03c | D24: 1783609190.782335 | E24: 1783609192.5468304 | F24: =E24-D24 -> 1.7644999 | G24: -112 | H24: -1.25 | I24: 44.637602 | J24: -63.588443 | K24: 52 | L24: 3 | M24: 3 | N24: =L24-M24 -> 0
A25: 50 | B25: 2828412009 | C25: !dadfb03c | D25: 1783609220.9005299 | E25: 1783609222.8061585 | F25: =E25-D25 -> 1.9056299 | G25: -102 | H25: 6.5 | I25: 44.637636 | J25: -63.587785 | K25: 50 | L25: 3 | M25: 3 | N25: =L25-M25 -> 0
A26: 51 | B26: 3642589290 | C26: !dadfb03c | D26: 1783609251.024917 | E26: 1783609252.796444 | F26: =E26-D26 -> 1.7715299 | G26: -89 | H26: 8 | I26: 44.637533 | J26: -63.587479 | K26: 48 | L26: 3 | M26: 3 | N26: =L26-M26 -> 0
A27: 52 | B27: 3931657323 | C27: !dadfb03c | D27: 1783609281.149798 | E27: 1783609282.949196 | F27: =E27-D27 -> 1.7993999 | G27: -68 | H27: 8 | I27: 44.637411 | J27: -63.587319 | K27: 68 | L27: 3 | M27: 3 | N27: =L27-M27 -> 0

Sheet dynamic_test_7hop
A1: localID | B1: packetID | C1: nodeID | D1: sendTime | E1: receivedTime | F1: latency | G1: rssi | H1: snr | I1: lat | J1: long | K1: alt | L1: hopStart | M1: hopLimit | N1: hopsUsed | O1: delivery rate (%) | P1: avg latency | Q1: distance to goldberg desktop (m) | R1: d to goldberg window | S1: d to rowe | T1: d to mccain | U1: d to lsc | V1: d to dunn | W1: closest node
A2: 1 | B2: 190451840 | C2: !dadfb8d4 | D2: 1784212168.410265 | E2: 1784212170.2598076 | F2: =E2-D2 -> 1.84954 | G2: -47 | H2: 9.5 | I2: 44.637613 | J2: -63.587365 | K2: 48 | L2: 7 | M2: 7 | N2: =L2-M2 -> 0 | O2: =COUNT(A2:A63)/84*100 -> 73.809524 | P2: =AVERAGE(F2:F63) -> 6.4404013 | Q2: =2*6371000*ASIN( SQRT( SIN(RADIANS(extra!$O$2-I2)/2)^2+ COS(RADIANS(I2))*COS(RADIANS(extra!$O$2))* SIN(RADIANS(extra!$P$2-J2)/2)^2 ) ) -> 23.001236 | R2: =2*6371000*ASIN( SQRT( SIN(RADIANS(extra!$O$7-I2)/2)^2+ COS(RADIANS(I2))*COS(RADIANS(extra!$O$7))* SIN(RADIANS(extra!$P$7-J2)/2)^2 ) ) -> 23.845936 | S2: =2*6371000*ASIN( SQRT( SIN(RADIANS(extra!$O$5-I2)/2)^2+ COS(RADIANS(I2))*COS(RADIANS(extra!$O$5))* SIN(RADIANS(extra!$P$5-J2)/2)^2 ) ) -> 98.583529 | T2: =2*6371000*ASIN( SQRT( SIN(RADIANS(extra!$O$6-I2)/2)^2+ COS(RADIANS(I2))*COS(RADIANS(extra!$O$6))* SIN(RADIANS(extra!$P$6-J2)/2)^2 ) ) -> 218.97105 | U2: =2*6371000*ASIN( SQRT( SIN(RADIANS(extra!$O$3-I2)/2)^2+ COS(RADIANS(I2))*COS(RADIANS(extra!$O$3))* SIN(RADIANS(extra!$P$3-J2)/2)^2 ) ) -> 559.14507 | V2: =2*6371000*ASIN( SQRT( SIN(RADIANS(extra!$O$4-I2)/2)^2+ COS(RADIANS(I2))*COS(RADIANS(extra!$O$4))* SIN(RADIANS(extra!$P$4-J2)/2)^2 ) ) -> 463.58599 | W2: =MIN(Q2:V2) -> 23.001236
A3: 2 | B3: 2690944129 | C3: !dadfb8d4 | D3: 1784212188.540854 | E3: 1784212190.630114 | F3: =E3-D3 -> 2.0892601 | G3: -51 | H3: 9.25 | I3: 44.637613 | J3: -63.587365 | K3: 48 | L3: 7 | M3: 7 | N3: =L3-M3 -> 0 | Q3: =2*6371000*ASIN( SQRT( SIN(RADIANS(extra!$O$2-I3)/2)^2+ COS(RADIANS(I3))*COS(RADIANS(extra!$O$2))* SIN(RADIANS(extra!$P$2-J3)/2)^2 ) ) -> 23.001236 | R3: =2*6371000*ASIN( SQRT( SIN(RADIANS(extra!$O$7-I3)/2)^2+ COS(RADIANS(I3))*COS(RADIANS(extra!$O$7))* SIN(RADIANS(extra!$P$7-J3)/2)^2 ) ) -> 23.845936 | S3: =2*6371000*ASIN( SQRT( SIN(RADIANS(extra!$O$5-I3)/2)^2+ COS(RADIANS(I3))*COS(RADIANS(extra!$O$5))* SIN(RADIANS(extra!$P$5-J3)/2)^2 ) ) -> 98.583529 | T3: =2*6371000*ASIN( SQRT( SIN(RADIANS(extra!$O$6-I3)/2)^2+ COS(RADIANS(I3))*COS(RADIANS(extra!$O$6))* SIN(RADIANS(extra!$P$6-J3)/2)^2 ) ) -> 218.97105 | U3: =2*6371000*ASIN( SQRT( SIN(RADIANS(extra!$O$3-I3)/2)^2+ COS(RADIANS(I3))*COS(RADIANS(extra!$O$3))* SIN(RADIANS(extra!$P$3-J3)/2)^2 ) ) -> 559.14507 | V3: =2*6371000*ASIN( SQRT( SIN(RADIANS(extra!$O$4-I3)/2)^2+ COS(RADIANS(I3))*COS(RADIANS(extra!$O$4))* SIN(RADIANS(extra!$P$4-J3)/2)^2 ) ) -> 463.58599 | W3: =MIN(Q3:V3) -> 23.001236
A4: 3 | B4: 709841026 | C4: !dadfb8d4 | D4: 1784212208.6759942 | E4: 1784212210.3987322 | F4: =E4-D4 -> 1.7227399 | G4: -47 | H4: 10.5 | I4: 44.637613 | J4: -63.587365 | K4: 48 | L4: 7 | M4: 7 | N4: =L4-M4 -> 0 | Q4: =2*6371000*ASIN( SQRT( SIN(RADIANS(extra!$O$2-I4)/2)^2+ COS(RADIANS(I4))*COS(RADIANS(extra!$O$2))* SIN(RADIANS(extra!$P$2-J4)/2)^2 ) ) -> 23.001236 | R4: =2*6371000*ASIN( SQRT( SIN(RADIANS(extra!$O$7-I4)/2)^2+ COS(RADIANS(I4))*COS(RADIANS(extra!$O$7))* SIN(RADIANS(extra!$P$7-J4)/2)^2 ) ) -> 23.845936 | S4: =2*6371000*ASIN( SQRT( SIN(RADIANS(extra!$O$5-I4)/2)^2+ COS(RADIANS(I4))*COS(RADIANS(extra!$O$5))* SIN(RADIANS(extra!$P$5-J4)/2)^2 ) ) -> 98.583529 | T4: =2*6371000*ASIN( SQRT( SIN(RADIANS(extra!$O$6-I4)/2)^2+ COS(RADIANS(I4))*COS(RADIANS(extra!$O$6))* SIN(RADIANS(extra!$P$6-J4)/2)^2 ) ) -> 218.97105 | U4: =2*6371000*ASIN( SQRT( SIN(RADIANS(extra!$O$3-I4)/2)^2+ COS(RADIANS(I4))*COS(RADIANS(extra!$O$3))* SIN(RADIANS(extra!$P$3-J4)/2)^2 ) ) -> 559.14507 | V4: =2*6371000*ASIN( SQRT( SIN(RADIANS(extra!$O$4-I4)/2)^2+ COS(RADIANS(I4))*COS(RADIANS(extra!$O$4))* SIN(RADIANS(extra!$P$4-J4)/2)^2 ) ) -> 463.58599 | W4: =MIN(Q4:V4) -> 23.001236
A5: 4 | B5: 586772611 | C5: !dadfb8d4 | D5: 1784212228.7989619 | E5: 1784212231.376371 | F5: =E5-D5 -> 2.57741 | G5: -45 | H5: 10.5 | I5: 44.637613 | J5: -63.587365 | K5: 48 | L5: 7 | M5: 7 | N5: =L5-M5 -> 0 | Q5: =2*6371000*ASIN( SQRT( SIN(RADIANS(extra!$O$2-I5)/2)^2+ COS(RADIANS(I5))*COS(RADIANS(extra!$O$2))* SIN(RADIANS(extra!$P$2-J5)/2)^2 ) ) -> 23.001236 | R5: =2*6371000*ASIN( SQRT( SIN(RADIANS(extra!$O$7-I5)/2)^2+ COS(RADIANS(I5))*COS(RADIANS(extra!$O$7))* SIN(RADIANS(extra!$P$7-J5)/2)^2 ) ) -> 23.845936 | S5: =2*6371000*ASIN( SQRT( SIN(RADIANS(extra!$O$5-I5)/2)^2+ COS(RADIANS(I5))*COS(RADIANS(extra!$O$5))* SIN(RADIANS(extra!$P$5-J5)/2)^2 ) ) -> 98.583529 | T5: =2*6371000*ASIN( SQRT( SIN(RADIANS(extra!$O$6-I5)/2)^2+ COS(RADIANS(I5))*COS(RADIANS(extra!$O$6))* SIN(RADIANS(extra!$P$6-J5)/2)^2 ) ) -> 218.97105 | U5: =2*6371000*ASIN( SQRT( SIN(RADIANS(extra!$O$3-I5)/2)^2+ COS(RADIANS(I5))*COS(RADIANS(extra!$O$3))* SIN(RADIANS(extra!$P$3-J5)/2)^2 ) ) -> 559.14507 | V5: =2*6371000*ASIN( SQRT( SIN(RADIANS(extra!$O$4-I5)/2)^2+ COS(RADIANS(I5))*COS(RADIANS(extra!$O$4))* SIN(RADIANS(extra!$P$4-J5)/2)^2 ) ) -> 463.58599 | W5: =MIN(Q5:V5) -> 23.001236
A6: 5 | B6: 3214359684 | C6: !dadfb8d4 | D6: 1784212248.920191 | E6: 1784212250.8501413 | F6: =E6-D6 -> 1.92995 | G6: -46 | H6: 10.25 | I6: 44.637613 | J6: -63.587365 | K6: 48 | L6: 7 | M6: 7 | N6: =L6-M6 -> 0 | Q6: =2*6371000*ASIN( SQRT( SIN(RADIANS(extra!$O$2-I6)/2)^2+ COS(RADIANS(I6))*COS(RADIANS(extra!$O$2))* SIN(RADIANS(extra!$P$2-J6)/2)^2 ) ) -> 23.001236 | R6: =2*6371000*ASIN( SQRT( SIN(RADIANS(extra!$O$7-I6)/2)^2+ COS(RADIANS(I6))*COS(RADIANS(extra!$O$7))* SIN(RADIANS(extra!$P$7-J6)/2)^2 ) ) -> 23.845936 | S6: =2*6371000*ASIN( SQRT( SIN(RADIANS(extra!$O$5-I6)/2)^2+ COS(RADIANS(I6))*COS(RADIANS(extra!$O$5))* SIN(RADIANS(extra!$P$5-J6)/2)^2 ) ) -> 98.583529 | T6: =2*6371000*ASIN( SQRT( SIN(RADIANS(extra!$O$6-I6)/2)^2+ COS(RADIANS(I6))*COS(RADIANS(extra!$O$6))* SIN(RADIANS(extra!$P$6-J6)/2)^2 ) ) -> 218.97105 | U6: =2*6371000*ASIN( SQRT( SIN(RADIANS(extra!$O$3-I6)/2)^2+ COS(RADIANS(I6))*COS(RADIANS(extra!$O$3))* SIN(RADIANS(extra!$P$3-J6)/2)^2 ) ) -> 559.14507 | V6: =2*6371000*ASIN( SQRT( SIN(RADIANS(extra!$O$4-I6)/2)^2+ COS(RADIANS(I6))*COS(RADIANS(extra!$O$4))* SIN(RADIANS(extra!$P$4-J6)/2)^2 ) ) -> 463.58599 | W6: =MIN(Q6:V6) -> 23.001236
A7: 6 | B7: 3688805509 | C7: !dadfb8d4 | D7: 1784212269.049736 | E7: 1784212271.0651937 | F7: =E7-D7 -> 2.01546 | G7: -43 | H7: 9.25 | I7: 44.637613 | J7: -63.587366 | K7: 48 | L7: 7 | M7: 7 | N7: =L7-M7 -> 0 | Q7: =2*6371000*ASIN( SQRT( SIN(RADIANS(extra!$O$2-I7)/2)^2+ COS(RADIANS(I7))*COS(RADIANS(extra!$O$2))* SIN(RADIANS(extra!$P$2-J7)/2)^2 ) ) -> 23.027757 | R7: =2*6371000*ASIN( SQRT( SIN(RADIANS(extra!$O$7-I7)/2)^2+ COS(RADIANS(I7))*COS(RADIANS(extra!$O$7))* SIN(RADIANS(extra!$P$7-J7)/2)^2 ) ) -> 23.807969 | S7: =2*6371000*ASIN( SQRT( SIN(RADIANS(extra!$O$5-I7)/2)^2+ COS(RADIANS(I7))*COS(RADIANS(extra!$O$5))* SIN(RADIANS(extra!$P$5-J7)/2)^2 ) ) -> 98.514 | T7: =2*6371000*ASIN( SQRT( SIN(RADIANS(extra!$O$6-I7)/2)^2+ COS(RADIANS(I7))*COS(RADIANS(extra!$O$6))* SIN(RADIANS(extra!$P$6-J7)/2)^2 ) ) -> 218.89202 | U7: =2*6371000*ASIN( SQRT( SIN(RADIANS(extra!$O$3-I7)/2)^2+ COS(RADIANS(I7))*COS(RADIANS(extra!$O$3))* SIN(RADIANS(extra!$P$3-J7)/2)^2 ) ) -> 559.06947 | V7: =2*6371000*ASIN( SQRT( SIN(RADIANS(extra!$O$4-I7)/2)^2+ COS(RADIANS(I7))*COS(RADIANS(extra!$O$4))* SIN(RADIANS(extra!$P$4-J7)/2)^2 ) ) -> 463.50687 | W7: =MIN(Q7:V7) -> 23.027757
A8: 7 | B8: 1246024838 | C8: !dadfb8d4 | D8: 1784212289.1705651 | E8: 1784212292.6885967 | F8: =E8-D8 -> 3.5180302 | G8: -39 | H8: 10.25 | I8: 44.637613 | J8: -63.587366 | K8: 48 | L8: 7 | M8: 7 | N8: =L8-M8 -> 0 | Q8: =2*6371000*ASIN( SQRT( SIN(RADIANS(extra!$O$2-I8)/2)^2+ COS(RADIANS(I8))*COS(RADIANS(extra!$O$2))* SIN(RADIANS(extra!$P$2-J8)/2)^2 ) ) -> 23.027757 | R8: =2*6371000*ASIN( SQRT( SIN(RADIANS(extra!$O$7-I8)/2)^2+ COS(RADIANS(I8))*COS(RADIANS(extra!$O$7))* SIN(RADIANS(extra!$P$7-J8)/2)^2 ) ) -> 23.807969 | S8: =2*6371000*ASIN( SQRT( SIN(RADIANS(extra!$O$5-I8)/2)^2+ COS(RADIANS(I8))*COS(RADIANS(extra!$O$5))* SIN(RADIANS(extra!$P$5-J8)/2)^2 ) ) -> 98.514 | T8: =2*6371000*ASIN( SQRT( SIN(RADIANS(extra!$O$6-I8)/2)^2+ COS(RADIANS(I8))*COS(RADIANS(extra!$O$6))* SIN(RADIANS(extra!$P$6-J8)/2)^2 ) ) -> 218.89202 | U8: =2*6371000*ASIN( SQRT( SIN(RADIANS(extra!$O$3-I8)/2)^2+ COS(RADIANS(I8))*COS(RADIANS(extra!$O$3))* SIN(RADIANS(extra!$P$3-J8)/2)^2 ) ) -> 559.06947 | V8: =2*6371000*ASIN( SQRT( SIN(RADIANS(extra!$O$4-I8)/2)^2+ COS(RADIANS(I8))*COS(RADIANS(extra!$O$4))* SIN(RADIANS(extra!$P$4-J8)/2)^2 ) ) -> 463.50687 | W8: =MIN(Q8:V8) -> 23.027757
A9: 8 | B9: 435356807 | C9: !dadfb8d4 | D9: 1784212309.3046532 | E9: 1784212311.1957016 | F9: =E9-D9 -> 1.8910499 | G9: -39 | H9: 9.5 | I9: 44.637613 | J9: -63.587366 | K9: 48 | L9: 7 | M9: 7 | N9: =L9-M9 -> 0 | Q9: =2*6371000*ASIN( SQRT( SIN(RADIANS(extra!$O$2-I9)/2)^2+ COS(RADIANS(I9))*COS(RADIANS(extra!$O$2))* SIN(RADIANS(extra!$P$2-J9)/2)^2 ) ) -> 23.027757 | R9: =2*6371000*ASIN( SQRT( SIN(RADIANS(extra!$O$7-I9)/2)^2+ COS(RADIANS(I9))*COS(RADIANS(extra!$O$7))* SIN(RADIANS(extra!$P$7-J9)/2)^2 ) ) -> 23.807969 | S9: =2*6371000*ASIN( SQRT( SIN(RADIANS(extra!$O$5-I9)/2)^2+ COS(RADIANS(I9))*COS(RADIANS(extra!$O$5))* SIN(RADIANS(extra!$P$5-J9)/2)^2 ) ) -> 98.514 | T9: =2*6371000*ASIN( SQRT( SIN(RADIANS(extra!$O$6-I9)/2)^2+ COS(RADIANS(I9))*COS(RADIANS(extra!$O$6))* SIN(RADIANS(extra!$P$6-J9)/2)^2 ) ) -> 218.89202 | U9: =2*6371000*ASIN( SQRT( SIN(RADIANS(extra!$O$3-I9)/2)^2+ COS(RADIANS(I9))*COS(RADIANS(extra!$O$3))* SIN(RADIANS(extra!$P$3-J9)/2)^2 ) ) -> 559.06947 | V9: =2*6371000*ASIN( SQRT( SIN(RADIANS(extra!$O$4-I9)/2)^2+ COS(RADIANS(I9))*COS(RADIANS(extra!$O$4))* SIN(RADIANS(extra!$P$4-J9)/2)^2 ) ) -> 463.50687 | W9: =MIN(Q9:V9) -> 23.027757
A10: 9 | B10: 674494600 | C10: !dadfb8d4 | D10: 1784212329.424661 | E10: 1784212331.3750553 | F10: =E10-D10 -> 1.9503901 | G10: -40 | H10: 9.5 | I10: 44.637614 | J10: -63.587366 | K10: 48 | L10: 7 | M10: 7 | N10: =L10-M10 -> 0 | Q10: =2*6371000*ASIN( SQRT( SIN(RADIANS(extra!$O$2-I10)/2)^2+ COS(RADIANS(I10))*COS(RADIANS(extra!$O$2))* SIN(RADIANS(extra!$P$2-J10)/2)^2 ) ) -> 23.132489 | R10: =2*6371000*ASIN( SQRT( SIN(RADIANS(extra!$O$7-I10)/2)^2+ COS(RADIANS(I10))*COS(RADIANS(extra!$O$7))* SIN(RADIANS(extra!$P$7-J10)/2)^2 ) ) -> 23.905663 | S10: =2*6371000*ASIN( SQRT( SIN(RADIANS(extra!$O$5-I10)/2)^2+ COS(RADIANS(I10))*COS(RADIANS(extra!$O$5))* SIN(RADIANS(extra!$P$5-J10)/2)^2 ) ) -> 98.567138 | T10: =2*6371000*ASIN( SQRT( SIN(RADIANS(extra!$O$6-I10)/2)^2+ COS(RADIANS(I10))*COS(RADIANS(extra!$O$6))* SIN(RADIANS(extra!$P$6-J10)/2)^2 ) ) -> 218.88646 | U10: =2*6371000*ASIN( SQRT( SIN(RADIANS(extra!$O$3-I10)/2)^2+ COS(RADIANS(I10))*COS(RADIANS(extra!$O$3))* SIN(RADIANS(extra!$P$3-J10)/2)^2 ) ) -> 559.1023 | V10: =2*6371000*ASIN( SQRT( SIN(RADIANS(extra!$O$4-I10)/2)^2+ COS(RADIANS(I10))*COS(RADIANS(extra!$O$4))* SIN(RADIANS(extra!$P$4-J10)/2)^2 ) ) -> 463.50752 | W10: =MIN(Q10:V10) -> 23.132489
A11: 10 | B11: 2629210249 | C11: !dadfb8d4 | D11: 1784212349.5472698 | E11: 1784212351.4381232 | F11: =E11-D11 -> 1.8908598 | G11: -72 | H11: 10 | I11: 44.637614 | J11: -63.587366 | K11: 48 | L11: 7 | M11: 7 | N11: =L11-M11 -> 0 | Q11: =2*6371000*ASIN( SQRT( SIN(RADIANS(extra!$O$2-I11)/2)^2+ COS(RADIANS(I11))*COS(RADIANS(extra!$O$2))* SIN(RADIANS(extra!$P$2-J11)/2)^2 ) ) -> 23.132489 | R11: =2*6371000*ASIN( SQRT( SIN(RADIANS(extra!$O$7-I11)/2)^2+ COS(RADIANS(I11))*COS(RADIANS(extra!$O$7))* SIN(RADIANS(extra!$P$7-J11)/2)^2 ) ) -> 23.905663 | S11: =2*6371000*ASIN( SQRT( SIN(RADIANS(extra!$O$5-I11)/2)^2+ COS(RADIANS(I11))*COS(RADIANS(extra!$O$5))* SIN(RADIANS(extra!$P$5-J11)/2)^2 ) ) -> 98.567138 | T11: =2*6371000*ASIN( SQRT( SIN(RADIANS(extra!$O$6-I11)/2)^2+ COS(RADIANS(I11))*COS(RADIANS(extra!$O$6))* SIN(RADIANS(extra!$P$6-J11)/2)^2 ) ) -> 218.88646 | U11: =2*6371000*ASIN( SQRT( SIN(RADIANS(extra!$O$3-I11)/2)^2+ COS(RADIANS(I11))*COS(RADIANS(extra!$O$3))* SIN(RADIANS(extra!$P$3-J11)/2)^2 ) ) -> 559.1023 | V11: =2*6371000*ASIN( SQRT( SIN(RADIANS(extra!$O$4-I11)/2)^2+ COS(RADIANS(I11))*COS(RADIANS(extra!$O$4))* SIN(RADIANS(extra!$P$4-J11)/2)^2 ) ) -> 463.50752 | W11: =MIN(Q11:V11) -> 23.132489
A12: 11 | B12: 3443336330 | C12: !dadfb8d4 | D12: 1784212369.663309 | E12: 1784212371.5300279 | F12: =E12-D12 -> 1.86672 | G12: -92 | H12: 9.75 | I12: 44.637614 | J12: -63.587366 | K12: 48 | L12: 7 | M12: 7 | N12: =L12-M12 -> 0 | Q12: =2*6371000*ASIN( SQRT( SIN(RADIANS(extra!$O$2-I12)/2)^2+ COS(RADIANS(I12))*COS(RADIANS(extra!$O$2))* SIN(RADIANS(extra!$P$2-J12)/2)^2 ) ) -> 23.132489 | R12: =2*6371000*ASIN( SQRT( SIN(RADIANS(extra!$O$7-I12)/2)^2+ COS(RADIANS(I12))*COS(RADIANS(extra!$O$7))* SIN(RADIANS(extra!$P$7-J12)/2)^2 ) ) -> 23.905663 | S12: =2*6371000*ASIN( SQRT( SIN(RADIANS(extra!$O$5-I12)/2)^2+ COS(RADIANS(I12))*COS(RADIANS(extra!$O$5))* SIN(RADIANS(extra!$P$5-J12)/2)^2 ) ) -> 98.567138 | T12: =2*6371000*ASIN( SQRT( SIN(RADIANS(extra!$O$6-I12)/2)^2+ COS(RADIANS(I12))*COS(RADIANS(extra!$O$6))* SIN(RADIANS(extra!$P$6-J12)/2)^2 ) ) -> 218.88646 | U12: =2*6371000*ASIN( SQRT( SIN(RADIANS(extra!$O$3-I12)/2)^2+ COS(RADIANS(I12))*COS(RADIANS(extra!$O$3))* SIN(RADIANS(extra!$P$3-J12)/2)^2 ) ) -> 559.1023 | V12: =2*6371000*ASIN( SQRT( SIN(RADIANS(extra!$O$4-I12)/2)^2+ COS(RADIANS(I12))*COS(RADIANS(extra!$O$4))* SIN(RADIANS(extra!$P$4-J12)/2)^2 ) ) -> 463.50752 | W12: =MIN(Q12:V12) -> 23.132489
A13: 12 | B13: 475634827 | C13: !dadfb8d4 | D13: 1784212389.799488 | E13: 1784212391.9080417 | F13: =E13-D13 -> 2.1085601 | G13: -91 | H13: 9.25 | I13: 44.637518 | J13: -63.587411 | K13: 46 | L13: 7 | M13: 7 | N13: =L13-M13 -> 0 | Q13: =2*6371000*ASIN( SQRT( SIN(RADIANS(extra!$O$2-I13)/2)^2+ COS(RADIANS(I13))*COS(RADIANS(extra!$O$2))* SIN(RADIANS(extra!$P$2-J13)/2)^2 ) ) -> 15.863851 | R13: =2*6371000*ASIN( SQRT( SIN(RADIANS(extra!$O$7-I13)/2)^2+ COS(RADIANS(I13))*COS(RADIANS(extra!$O$7))* SIN(RADIANS(extra!$P$7-J13)/2)^2 ) ) -> 12.972933 | S13: =2*6371000*ASIN( SQRT( SIN(RADIANS(extra!$O$5-I13)/2)^2+ COS(RADIANS(I13))*COS(RADIANS(extra!$O$5))* SIN(RADIANS(extra!$P$5-J13)/2)^2 ) ) -> 90.659615 | T13: =2*6371000*ASIN( SQRT( SIN(RADIANS(extra!$O$6-I13)/2)^2+ COS(RADIANS(I13))*COS(RADIANS(extra!$O$6))* SIN(RADIANS(extra!$P$6-J13)/2)^2 ) ) -> 216.13392 | U13: =2*6371000*ASIN( SQRT( SIN(RADIANS(extra!$O$3-I13)/2)^2+ COS(RADIANS(I13))*COS(RADIANS(extra!$O$3))* SIN(RADIANS(extra!$P$3-J13)/2)^2 ) ) -> 552.62404 | V13: =2*6371000*ASIN( SQRT( SIN(RADIANS(extra!$O$4-I13)/2)^2+ COS(RADIANS(I13))*COS(RADIANS(extra!$O$4))* SIN(RADIANS(extra!$P$4-J13)/2)^2 ) ) -> 460.00681 | W13: =MIN(Q13:V13) -> 12.972933
A14: 13 | B14: 1740768396 | C14: !dadfb8d4 | D14: 1784212409.916245 | E14: 1784212415.478573 | F14: =E14-D14 -> 5.56233 | G14: -83 | H14: 8.75 | I14: 44.637466 | J14: -63.587731 | K14: 48 | L14: 7 | M14: 6 | N14: =L14-M14 -> 1 | Q14: =2*6371000*ASIN( SQRT( SIN(RADIANS(extra!$O$2-I14)/2)^2+ COS(RADIANS(I14))*COS(RADIANS(extra!$O$2))* SIN(RADIANS(extra!$P$2-J14)/2)^2 ) ) -> 37.020556 | R14: =2*6371000*ASIN( SQRT( SIN(RADIANS(extra!$O$7-I14)/2)^2+ COS(RADIANS(I14))*COS(RADIANS(extra!$O$7))* SIN(RADIANS(extra!$P$7-J14)/2)^2 ) ) -> 18.070645 | S14: =2*6371000*ASIN( SQRT( SIN(RADIANS(extra!$O$5-I14)/2)^2+ COS(RADIANS(I14))*COS(RADIANS(extra!$O$5))* SIN(RADIANS(extra!$P$5-J14)/2)^2 ) ) -> 65.336869 | T14: =2*6371000*ASIN( SQRT( SIN(RADIANS(extra!$O$6-I14)/2)^2+ COS(RADIANS(I14))*COS(RADIANS(extra!$O$6))* SIN(RADIANS(extra!$P$6-J14)/2)^2 ) ) -> 191.69728 | U14: =2*6371000*ASIN( SQRT( SIN(RADIANS(extra!$O$3-I14)/2)^2+ COS(RADIANS(I14))*COS(RADIANS(extra!$O$3))* SIN(RADIANS(extra!$P$3-J14)/2)^2 ) ) -> 526.69991 | V14: =2*6371000*ASIN( SQRT( SIN(RADIANS(extra!$O$4-I14)/2)^2+ COS(RADIANS(I14))*COS(RADIANS(extra!$O$4))* SIN(RADIANS(extra!$P$4-J14)/2)^2 ) ) -> 434.8352 | W14: =MIN(Q14:V14) -> 18.070645
... A20: 24 | B20: 3152866455 | C20: !dadfb8d4 | D20: 1784212631.269245 | E20: 1784212638.9650795 | F20: =E20-D20 -> 7.6958301 | G20: -86 | H20: 7.25 | I20: 44.636653 | J20: -63.58862 | K20: 49 | L20: 7 | M20: 6 | N20: =L20-M20 -> 1 | Q20: =2*6371000*ASIN( SQRT( SIN(RADIANS(extra!$O$2-I20)/2)^2+ COS(RADIANS(I20))*COS(RADIANS(extra!$O$2))* SIN(RADIANS(extra!$P$2-J20)/2)^2 ) ) -> 136.67283 | R20: =2*6371000*ASIN( SQRT( SIN(RADIANS(extra!$O$7-I20)/2)^2+ COS(RADIANS(I20))*COS(RADIANS(extra!$O$7))* SIN(RADIANS(extra!$P$7-J20)/2)^2 ) ) -> 122.81071 | S20: =2*6371000*ASIN( SQRT( SIN(RADIANS(extra!$O$5-I20)/2)^2+ COS(RADIANS(I20))*COS(RADIANS(extra!$O$5))* SIN(RADIANS(extra!$P$5-J20)/2)^2 ) ) -> 61.038948 | T20: =2*6371000*ASIN( SQRT( SIN(RADIANS(extra!$O$6-I20)/2)^2+ COS(RADIANS(I20))*COS(RADIANS(extra!$O$6))* SIN(RADIANS(extra!$P$6-J20)/2)^2 ) ) -> 167.69583 | U20: =2*6371000*ASIN( SQRT( SIN(RADIANS(extra!$O$3-I20)/2)^2+ COS(RADIANS(I20))*COS(RADIANS(extra!$O$3))* SIN(RADIANS(extra!$P$3-J20)/2)^2 ) ) -> 438.83043 | V20: =2*6371000*ASIN( SQRT( SIN(RADIANS(extra!$O$4-I20)/2)^2+ COS(RADIANS(I20))*COS(RADIANS(extra!$O$4))* SIN(RADIANS(extra!$P$4-J20)/2)^2 ) ) -> 378.85907 | W20: =MIN(Q20:V20) -> 61.038948
A21: 25 | B21: 1632407704 | C21: !dadfb8d4 | D21: 1784212651.3964338 | E21: 1.7842127e+09 | F21: =E21-D21 -> 6.98387 | G21: -86 | H21: 7.75 | I21: 44.636989 | J21: -63.588751 | K21: 51 | L21: 7 | M21: 6 | N21: =L21-M21 -> 1 | Q21: =2*6371000*ASIN( SQRT( SIN(RADIANS(extra!$O$2-I21)/2)^2+ COS(RADIANS(I21))*COS(RADIANS(extra!$O$2))* SIN(RADIANS(extra!$P$2-J21)/2)^2 ) ) -> 126.66518 | R21: =2*6371000*ASIN( SQRT( SIN(RADIANS(extra!$O$7-I21)/2)^2+ COS(RADIANS(I21))*COS(RADIANS(extra!$O$7))* SIN(RADIANS(extra!$P$7-J21)/2)^2 ) ) -> 109.50798 | S21: =2*6371000*ASIN( SQRT( SIN(RADIANS(extra!$O$5-I21)/2)^2+ COS(RADIANS(I21))*COS(RADIANS(extra!$O$5))* SIN(RADIANS(extra!$P$5-J21)/2)^2 ) ) -> 32.088524 | T21: =2*6371000*ASIN( SQRT( SIN(RADIANS(extra!$O$6-I21)/2)^2+ COS(RADIANS(I21))*COS(RADIANS(extra!$O$6))* SIN(RADIANS(extra!$P$6-J21)/2)^2 ) ) -> 135.4658 | U21: =2*6371000*ASIN( SQRT( SIN(RADIANS(extra!$O$3-I21)/2)^2+ COS(RADIANS(I21))*COS(RADIANS(extra!$O$3))* SIN(RADIANS(extra!$P$3-J21)/2)^2 ) ) -> 435.21444 | V21: =2*6371000*ASIN( SQRT( SIN(RADIANS(extra!$O$4-I21)/2)^2+ COS(RADIANS(I21))*COS(RADIANS(extra!$O$4))* SIN(RADIANS(extra!$P$4-J21)/2)^2 ) ) -> 360.15005 | W21: =MIN(Q21:V21) -> 32.088524
A22: 26 | B22: 3334529177 | C22: !dadfb8d4 | D22: 1784212671.519526 | E22: 1784212673.6503875 | F22: =E22-D22 -> 2.1308599 | G22: -116 | H22: -10.25 | I22: 44.637076 | J22: -63.589096 | K22: 51 | L22: 7 | M22: 7 | N22: =L22-M22 -> 0 | Q22: =2*6371000*ASIN( SQRT( SIN(RADIANS(extra!$O$2-I22)/2)^2+ COS(RADIANS(I22))*COS(RADIANS(extra!$O$2))* SIN(RADIANS(extra!$P$2-J22)/2)^2 ) ) -> 149.5525 | R22: =2*6371000*ASIN( SQRT( SIN(RADIANS(extra!$O$7-I22)/2)^2+ COS(RADIANS(I22))*COS(RADIANS(extra!$O$7))* SIN(RADIANS(extra!$P$7-J22)/2)^2 ) ) -> 131.35242 | S22: =2*6371000*ASIN( SQRT( SIN(RADIANS(extra!$O$5-I22)/2)^2+ COS(RADIANS(I22))*COS(RADIANS(extra!$O$5))* SIN(RADIANS(extra!$P$5-J22)/2)^2 ) ) -> 51.894292 | T22: =2*6371000*ASIN( SQRT( SIN(RADIANS(extra!$O$6-I22)/2)^2+ COS(RADIANS(I22))*COS(RADIANS(extra!$O$6))* SIN(RADIANS(extra!$P$6-J22)/2)^2 ) ) -> 108.08202 | U22: =2*6371000*ASIN( SQRT( SIN(RADIANS(extra!$O$3-I22)/2)^2+ COS(RADIANS(I22))*COS(RADIANS(extra!$O$3))* SIN(RADIANS(extra!$P$3-J22)/2)^2 ) ) -> 410.9991 | V22: =2*6371000*ASIN( SQRT( SIN(RADIANS(extra!$O$4-I22)/2)^2+ COS(RADIANS(I22))*COS(RADIANS(extra!$O$4))* SIN(RADIANS(extra!$P$4-J22)/2)^2 ) ) -> 331.56268 | W22: =MIN(Q22:V22) -> 51.894292
A23: 28 | B23: 1103081627 | C23: !dadfb8d4 | D23: 1784212711.7926881 | E23: 1784212721.268213 | F23: =E23-D23 -> 9.4755299 | G23: -85 | H23: 8 | I23: 44.636785 | J23: -63.589906 | K23: 49 | L23: 7 | M23: 6 | N23: =L23-M23 -> 1 | Q23: =2*6371000*ASIN( SQRT( SIN(RADIANS(extra!$O$2-I23)/2)^2+ COS(RADIANS(I23))*COS(RADIANS(extra!$O$2))* SIN(RADIANS(extra!$P$2-J23)/2)^2 ) ) -> 220.27507 | R23: =2*6371000*ASIN( SQRT( SIN(RADIANS(extra!$O$7-I23)/2)^2+ COS(RADIANS(I23))*COS(RADIANS(extra!$O$7))* SIN(RADIANS(extra!$P$7-J23)/2)^2 ) ) -> 202.49594 | S23: =2*6371000*ASIN( SQRT( SIN(RADIANS(extra!$O$5-I23)/2)^2+ COS(RADIANS(I23))*COS(RADIANS(extra!$O$5))* SIN(RADIANS(extra!$P$5-J23)/2)^2 ) ) -> 122.95616 | T23: =2*6371000*ASIN( SQRT( SIN(RADIANS(extra!$O$6-I23)/2)^2+ COS(RADIANS(I23))*COS(RADIANS(extra!$O$6))* SIN(RADIANS(extra!$P$6-J23)/2)^2 ) ) -> 104.57694 | U23: =2*6371000*ASIN( SQRT( SIN(RADIANS(extra!$O$3-I23)/2)^2+ COS(RADIANS(I23))*COS(RADIANS(extra!$O$3))* SIN(RADIANS(extra!$P$3-J23)/2)^2 ) ) -> 341.08229 | V23: =2*6371000*ASIN( SQRT( SIN(RADIANS(extra!$O$4-I23)/2)^2+ COS(RADIANS(I23))*COS(RADIANS(extra!$O$4))* SIN(RADIANS(extra!$P$4-J23)/2)^2 ) ) -> 277.3347 | W23: =MIN(Q23:V23) -> 104.57694
A24: 29 | B24: 3145167004 | C24: !dadfb8d4 | D24: 1784212731.9222558 | E24: 1784212736.175619 | F24: =E24-D24 -> 4.25336 | G24: -86 | H24: 7.75 | I24: 44.636721 | J24: -63.590263 | K24: 50 | L24: 7 | M24: 6 | N24: =L24-M24 -> 1 | Q24: =2*6371000*ASIN( SQRT( SIN(RADIANS(extra!$O$2-I24)/2)^2+ COS(RADIANS(I24))*COS(RADIANS(extra!$O$2))* SIN(RADIANS(extra!$P$2-J24)/2)^2 ) ) -> 249.32568 | R24: =2*6371000*ASIN( SQRT( SIN(RADIANS(extra!$O$7-I24)/2)^2+ COS(RADIANS(I24))*COS(RADIANS(extra!$O$7))* SIN(RADIANS(extra!$P$7-J24)/2)^2 ) ) -> 231.46518 | S24: =2*6371000*ASIN( SQRT( SIN(RADIANS(extra!$O$5-I24)/2)^2+ COS(RADIANS(I24))*COS(RADIANS(extra!$O$5))* SIN(RADIANS(extra!$P$5-J24)/2)^2 ) ) -> 151.89256 | T24: =2*6371000*ASIN( SQRT( SIN(RADIANS(extra!$O$6-I24)/2)^2+ COS(RADIANS(I24))*COS(RADIANS(extra!$O$6))* SIN(RADIANS(extra!$P$6-J24)/2)^2 ) ) -> 110.70306 | U24: =2*6371000*ASIN( SQRT( SIN(RADIANS(extra!$O$3-I24)/2)^2+ COS(RADIANS(I24))*COS(RADIANS(extra!$O$3))* SIN(RADIANS(extra!$P$3-J24)/2)^2 ) ) -> 311.96811 | V24: =2*6371000*ASIN( SQRT( SIN(RADIANS(extra!$O$4-I24)/2)^2+ COS(RADIANS(I24))*COS(RADIANS(extra!$O$4))* SIN(RADIANS(extra!$P$4-J24)/2)^2 ) ) -> 253.38556 | W24: =MIN(Q24:V24) -> 110.70306
A25: 31 | B25: 1149179038 | C25: !dadfb8d4 | D25: 1784212772.1857831 | E25: 1784212778.960868 | F25: =E25-D25 -> 6.77508 | G25: -90 | H25: 8 | I25: 44.636432 | J25: -63.590829 | K25: 50 | L25: 7 | M25: 6 | N25: =L25-M25 -> 1 | Q25: =2*6371000*ASIN( SQRT( SIN(RADIANS(extra!$O$2-I25)/2)^2+ COS(RADIANS(I25))*COS(RADIANS(extra!$O$2))* SIN(RADIANS(extra!$P$2-J25)/2)^2 ) ) -> 302.33797 | R25: =2*6371000*ASIN( SQRT( SIN(RADIANS(extra!$O$7-I25)/2)^2+ COS(RADIANS(I25))*COS(RADIANS(extra!$O$7))* SIN(RADIANS(extra!$P$7-J25)/2)^2 ) ) -> 284.87898 | S25: =2*6371000*ASIN( SQRT( SIN(RADIANS(extra!$O$5-I25)/2)^2+ COS(RADIANS(I25))*COS(RADIANS(extra!$O$5))* SIN(RADIANS(extra!$P$5-J25)/2)^2 ) ) -> 205.52174 | T25: =2*6371000*ASIN( SQRT( SIN(RADIANS(extra!$O$6-I25)/2)^2+ COS(RADIANS(I25))*COS(RADIANS(extra!$O$6))* SIN(RADIANS(extra!$P$6-J25)/2)^2 ) ) -> 152.72629 | U25: =2*6371000*ASIN( SQRT( SIN(RADIANS(extra!$O$3-I25)/2)^2+ COS(RADIANS(I25))*COS(RADIANS(extra!$O$3))* SIN(RADIANS(extra!$P$3-J25)/2)^2 ) ) -> 262.33304 | V25: =2*6371000*ASIN( SQRT( SIN(RADIANS(extra!$O$4-I25)/2)^2+ COS(RADIANS(I25))*COS(RADIANS(extra!$O$4))* SIN(RADIANS(extra!$P$4-J25)/2)^2 ) ) -> 229.04536 | W25: =MIN(Q25:V25) -> 152.72629
A26: 32 | B26: 3205685407 | C26: !dadfb8d4 | D26: 1784212792.317417 | E26: 1784212796.6252182 | F26: =E26-D26 -> 4.3078001 | G26: -86 | H26: 6.5 | I26: 44.6362 | J26: -63.591097 | K26: 50 | L26: 7 | M26: 6 | N26: =L26-M26 -> 1 | Q26: =2*6371000*ASIN( SQRT( SIN(RADIANS(extra!$O$2-I26)/2)^2+ COS(RADIANS(I26))*COS(RADIANS(extra!$O$2))* SIN(RADIANS(extra!$P$2-J26)/2)^2 ) ) -> 331.85823 | R26: =2*6371000*ASIN( SQRT( SIN(RADIANS(extra!$O$7-I26)/2)^2+ COS(RADIANS(I26))*COS(RADIANS(extra!$O$7))* SIN(RADIANS(extra!$P$7-J26)/2)^2 ) ) -> 314.81061 | S26: =2*6371000*ASIN( SQRT( SIN(RADIANS(extra!$O$5-I26)/2)^2+ COS(RADIANS(I26))*COS(RADIANS(extra!$O$5))* SIN(RADIANS(extra!$P$5-J26)/2)^2 ) ) -> 235.90827 | T26: =2*6371000*ASIN( SQRT( SIN(RADIANS(extra!$O$6-I26)/2)^2+ COS(RADIANS(I26))*COS(RADIANS(extra!$O$6))* SIN(RADIANS(extra!$P$6-J26)/2)^2 ) ) -> 184.75073 | U26: =2*6371000*ASIN( SQRT( SIN(RADIANS(extra!$O$3-I26)/2)^2+ COS(RADIANS(I26))*COS(RADIANS(extra!$O$3))* SIN(RADIANS(extra!$P$3-J26)/2)^2 ) ) -> 239.08603 | V26: =2*6371000*ASIN( SQRT( SIN(RADIANS(extra!$O$4-I26)/2)^2+ COS(RADIANS(I26))*COS(RADIANS(extra!$O$4))* SIN(RADIANS(extra!$P$4-J26)/2)^2 ) ) -> 228.42523 | W26: =MIN(Q26:V26) -> 184.75073
A27: 33 | B27: 2826881184 | C27: !dadfb8d4 | D27: 1784212812.444996 | E27: 1784212820.4770436 | F27: =E27-D27 -> 8.0320501 | G27: -84 | H27: 8.25 | I27: 44.636093 | J27: -63.591473 | K27: 50 | L27: 7 | M27: 5 | N27: =L27-M27 -> 2 | Q27: =2*6371000*ASIN( SQRT( SIN(RADIANS(extra!$O$2-I27)/2)^2+ COS(RADIANS(I27))*COS(RADIANS(extra!$O$2))* SIN(RADIANS(extra!$P$2-J27)/2)^2 ) ) -> 363.87655 | R27: =2*6371000*ASIN( SQRT( SIN(RADIANS(extra!$O$7-I27)/2)^2+ COS(RADIANS(I27))*COS(RADIANS(extra!$O$7))* SIN(RADIANS(extra!$P$7-J27)/2)^2 ) ) -> 346.7869 | S27: =2*6371000*ASIN( SQRT( SIN(RADIANS(extra!$O$5-I27)/2)^2+ COS(RADIANS(I27))*COS(RADIANS(extra!$O$5))* SIN(RADIANS(extra!$P$5-J27)/2)^2 ) ) -> 267.79432 | T27: =2*6371000*ASIN( SQRT( SIN(RADIANS(extra!$O$6-I27)/2)^2+ COS(RADIANS(I27))*COS(RADIANS(extra!$O$6))* SIN(RADIANS(extra!$P$6-J27)/2)^2 ) ) -> 209.08715 | U27: =2*6371000*ASIN( SQRT( SIN(RADIANS(extra!$O$3-I27)/2)^2+ COS(RADIANS(I27))*COS(RADIANS(extra!$O$3))* SIN(RADIANS(extra!$P$3-J27)/2)^2 ) ) -> 209.24337 | V27: =2*6371000*ASIN( SQRT( SIN(RADIANS(extra!$O$4-I27)/2)^2+ COS(RADIANS(I27))*COS(RADIANS(extra!$O$4))* SIN(RADIANS(extra!$P$4-J27)/2)^2 ) ) -> 216.48625 | W27: =MIN(Q27:V27) -> 209.08715
A28: 35 | B28: 991729826 | C28: !dadfb8d4 | D28: 1784212852.711106 | E28: 1784212858.801222 | F28: =E28-D28 -> 6.0901198 | G28: -85 | H28: 7.75 | I28: 44.635923 | J28: -63.592279 | K28: 50 | L28: 7 | M28: 5 | N28: =L28-M28 -> 2 | Q28: =2*6371000*ASIN( SQRT( SIN(RADIANS(extra!$O$2-I28)/2)^2+ COS(RADIANS(I28))*COS(RADIANS(extra!$O$2))* SIN(RADIANS(extra!$P$2-J28)/2)^2 ) ) -> 429.92785 | R28: =2*6371000*ASIN( SQRT( SIN(RADIANS(extra!$O$7-I28)/2)^2+ COS(RADIANS(I28))*COS(RADIANS(extra!$O$7))* SIN(RADIANS(extra!$P$7-J28)/2)^2 ) ) -> 412.65008 | S28: =2*6371000*ASIN( SQRT( SIN(RADIANS(extra!$O$5-I28)/2)^2+ COS(RADIANS(I28))*COS(RADIANS(extra!$O$5))* SIN(RADIANS(extra!$P$5-J28)/2)^2 ) ) -> 333.40278 | T28: =2*6371000*ASIN( SQRT( SIN(RADIANS(extra!$O$6-I28)/2)^2+ COS(RADIANS(I28))*COS(RADIANS(extra!$O$6))* SIN(RADIANS(extra!$P$6-J28)/2)^2 ) ) -> 261.74707 | U28: =2*6371000*ASIN( SQRT( SIN(RADIANS(extra!$O$3-I28)/2)^2+ COS(RADIANS(I28))*COS(RADIANS(extra!$O$3))* SIN(RADIANS(extra!$P$3-J28)/2)^2 ) ) -> 147.22384 | V28: =2*6371000*ASIN( SQRT( SIN(RADIANS(extra!$O$4-I28)/2)^2+ COS(RADIANS(I28))*COS(RADIANS(extra!$O$4))* SIN(RADIANS(extra!$P$4-J28)/2)^2 ) ) -> 199.77152 | W28: =MIN(Q28:V28) -> 147.22384
A29: 36 | B29: 1403428003 | C29: !dadfb8d4 | D29: 1784212872.828379 | E29: 1784212884.3639987 | F29: =E29-D29 -> 11.53562 | G29: -86 | H29: 7.5 | I29: 44.63589 | J29: -63.592698 | K29: 51 | L29: 7 | M29: 5 | N29: =L29-M29 -> 2 | Q29: =2*6371000*ASIN( SQRT( SIN(RADIANS(extra!$O$2-I29)/2)^2+ COS(RADIANS(I29))*COS(RADIANS(extra!$O$2))* SIN(RADIANS(extra!$P$2-J29)/2)^2 ) ) -> 462.01739 | R29: =2*6371000*ASIN( SQRT( SIN(RADIANS(extra!$O$7-I29)/2)^2+ COS(RADIANS(I29))*COS(RADIANS(extra!$O$7))* SIN(RADIANS(extra!$P$7-J29)/2)^2 ) ) -> 444.56528 | S29: =2*6371000*ASIN( SQRT( SIN(RADIANS(extra!$O$5-I29)/2)^2+ COS(RADIANS(I29))*COS(RADIANS(extra!$O$5))* SIN(RADIANS(extra!$P$5-J29)/2)^2 ) ) -> 365.15733 | T29: =2*6371000*ASIN( SQRT( SIN(RADIANS(extra!$O$6-I29)/2)^2+ COS(RADIANS(I29))*COS(RADIANS(extra!$O$6))* SIN(RADIANS(extra!$P$6-J29)/2)^2 ) ) -> 286.99062 | U29: =2*6371000*ASIN( SQRT( SIN(RADIANS(extra!$O$3-I29)/2)^2+ COS(RADIANS(I29))*COS(RADIANS(extra!$O$3))* SIN(RADIANS(extra!$P$3-J29)/2)^2 ) ) -> 115.3801 | V29: =2*6371000*ASIN( SQRT( SIN(RADIANS(extra!$O$4-I29)/2)^2+ COS(RADIANS(I29))*COS(RADIANS(extra!$O$4))* SIN(RADIANS(extra!$P$4-J29)/2)^2 ) ) -> 193.45019 | W29: =MIN(Q29:V29) -> 115.3801
A30: 38 | B30: 2423967909 | C30: !dadfb8d4 | D30: 1784212913.075424 | E30: 1784212921.857976 | F30: =E30-D30 -> 8.7825501 | G30: -86 | H30: 8.25 | I30: 44.635435 | J30: -63.593123 | K30: 50 | L30: 7 | M30: 4 | N30: =L30-M30 -> 3 | Q30: =2*6371000*ASIN( SQRT( SIN(RADIANS(extra!$O$2-I30)/2)^2+ COS(RADIANS(I30))*COS(RADIANS(extra!$O$2))* SIN(RADIANS(extra!$P$2-J30)/2)^2 ) ) -> 513.06944 | R30: =2*6371000*ASIN( SQRT( SIN(RADIANS(extra!$O$7-I30)/2)^2+ COS(RADIANS(I30))*COS(RADIANS(extra!$O$7))* SIN(RADIANS(extra!$P$7-J30)/2)^2 ) ) -> 496.19481 | S30: =2*6371000*ASIN( SQRT( SIN(RADIANS(extra!$O$5-I30)/2)^2+ COS(RADIANS(I30))*COS(RADIANS(extra!$O$5))* SIN(RADIANS(extra!$P$5-J30)/2)^2 ) ) -> 417.38588 | T30: =2*6371000*ASIN( SQRT( SIN(RADIANS(extra!$O$6-I30)/2)^2+ COS(RADIANS(I30))*COS(RADIANS(extra!$O$6))* SIN(RADIANS(extra!$P$6-J30)/2)^2 ) ) -> 346.73574 | U30: =2*6371000*ASIN( SQRT( SIN(RADIANS(extra!$O$3-I30)/2)^2+ COS(RADIANS(I30))*COS(RADIANS(extra!$O$3))* SIN(RADIANS(extra!$P$3-J30)/2)^2 ) ) -> 110.18596 | V30: =2*6371000*ASIN( SQRT( SIN(RADIANS(extra!$O$4-I30)/2)^2+ COS(RADIANS(I30))*COS(RADIANS(extra!$O$4))* SIN(RADIANS(extra!$P$4-J30)/2)^2 ) ) -> 239.64716 | W30: =MIN(Q30:V30) -> 110.18596
A31: 39 | B31: 372538534 | C31: !dadfb8d4 | D31: 1784212933.195333 | E31: 1784212943.918026 | F31: =E31-D31 -> 10.72269 | G31: -89 | H31: 9 | I31: 44.635233 | J31: -63.593425 | K31: 48 | L31: 7 | M31: 4 | N31: =L31-M31 -> 3 | Q31: =2*6371000*ASIN( SQRT( SIN(RADIANS(extra!$O$2-I31)/2)^2+ COS(RADIANS(I31))*COS(RADIANS(extra!$O$2))* SIN(RADIANS(extra!$P$2-J31)/2)^2 ) ) -> 544.39157 | R31: =2*6371000*ASIN( SQRT( SIN(RADIANS(extra!$O$7-I31)/2)^2+ COS(RADIANS(I31))*COS(RADIANS(extra!$O$7))* SIN(RADIANS(extra!$P$7-J31)/2)^2 ) ) -> 527.68458 | S31: =2*6371000*ASIN( SQRT( SIN(RADIANS(extra!$O$5-I31)/2)^2+ COS(RADIANS(I31))*COS(RADIANS(extra!$O$5))* SIN(RADIANS(extra!$P$5-J31)/2)^2 ) ) -> 449.09503 | T31: =2*6371000*ASIN( SQRT( SIN(RADIANS(extra!$O$6-I31)/2)^2+ COS(RADIANS(I31))*COS(RADIANS(extra!$O$6))* SIN(RADIANS(extra!$P$6-J31)/2)^2 ) ) -> 379.46927 | U31: =2*6371000*ASIN( SQRT( SIN(RADIANS(extra!$O$3-I31)/2)^2+ COS(RADIANS(I31))*COS(RADIANS(extra!$O$3))* SIN(RADIANS(extra!$P$3-J31)/2)^2 ) ) -> 113.68521 | V31: =2*6371000*ASIN( SQRT( SIN(RADIANS(extra!$O$4-I31)/2)^2+ COS(RADIANS(I31))*COS(RADIANS(extra!$O$4))* SIN(RADIANS(extra!$P$4-J31)/2)^2 ) ) -> 262.45755 | W31: =MIN(Q31:V31) -> 113.68521
A32: 40 | B32: 3271978151 | C32: !dadfb8d4 | D32: 1784212953.310785 | E32: 1784212962.5860183 | F32: =E32-D32 -> 9.2752299 | G32: -90 | H32: 8 | I32: 44.635108 | J32: -63.593803 | K32: 46 | L32: 7 | M32: 4 | N32: =L32-M32 -> 3 | Q32: =2*6371000*ASIN( SQRT( SIN(RADIANS(extra!$O$2-I32)/2)^2+ COS(RADIANS(I32))*COS(RADIANS(extra!$O$2))* SIN(RADIANS(extra!$P$2-J32)/2)^2 ) ) -> 577.36108 | R32: =2*6371000*ASIN( SQRT( SIN(RADIANS(extra!$O$7-I32)/2)^2+ COS(RADIANS(I32))*COS(RADIANS(extra!$O$7))* SIN(RADIANS(extra!$P$7-J32)/2)^2 ) ) -> 560.63433 | S32: =2*6371000*ASIN( SQRT( SIN(RADIANS(extra!$O$5-I32)/2)^2+ COS(RADIANS(I32))*COS(RADIANS(extra!$O$5))* SIN(RADIANS(extra!$P$5-J32)/2)^2 ) ) -> 481.99932 | T32: =2*6371000*ASIN( SQRT( SIN(RADIANS(extra!$O$6-I32)/2)^2+ COS(RADIANS(I32))*COS(RADIANS(extra!$O$6))* SIN(RADIANS(extra!$P$6-J32)/2)^2 ) ) -> 410.30189 | U32: =2*6371000*ASIN( SQRT( SIN(RADIANS(extra!$O$3-I32)/2)^2+ COS(RADIANS(I32))*COS(RADIANS(extra!$O$3))* SIN(RADIANS(extra!$P$3-J32)/2)^2 ) ) -> 116.21684 | V32: =2*6371000*ASIN( SQRT( SIN(RADIANS(extra!$O$4-I32)/2)^2+ COS(RADIANS(I32))*COS(RADIANS(extra!$O$4))* SIN(RADIANS(extra!$P$4-J32)/2)^2 ) ) -> 279.65268 | W32: =MIN(Q32:V32) -> 116.21684
A33: 42 | B33: 2287407273 | C33: !dadfb8d4 | D33: 1784212993.560777 | E33: 1784213005.0189629 | F33: =E33-D33 -> 11.45819 | G33: -90 | H33: 8.25 | I33: 44.63528 | J33: -63.594575 | K33: 44 | L33: 7 | M33: 4 | N33: =L33-M33 -> 3 | Q33: =2*6371000*ASIN( SQRT( SIN(RADIANS(extra!$O$2-I33)/2)^2+ COS(RADIANS(I33))*COS(RADIANS(extra!$O$2))* SIN(RADIANS(extra!$P$2-J33)/2)^2 ) ) -> 625.12948 | R33: =2*6371000*ASIN( SQRT( SIN(RADIANS(extra!$O$7-I33)/2)^2+ COS(RADIANS(I33))*COS(RADIANS(extra!$O$7))* SIN(RADIANS(extra!$P$7-J33)/2)^2 ) ) -> 607.7688 | S33: =2*6371000*ASIN( SQRT( SIN(RADIANS(extra!$O$5-I33)/2)^2+ COS(RADIANS(I33))*COS(RADIANS(extra!$O$5))* SIN(RADIANS(extra!$P$5-J33)/2)^2 ) ) -> 528.4054 | T33: =2*6371000*ASIN( SQRT( SIN(RADIANS(extra!$O$6-I33)/2)^2+ COS(RADIANS(I33))*COS(RADIANS(extra!$O$6))* SIN(RADIANS(extra!$P$6-J33)/2)^2 ) ) -> 443.71495 | U33: =2*6371000*ASIN( SQRT( SIN(RADIANS(extra!$O$3-I33)/2)^2+ COS(RADIANS(I33))*COS(RADIANS(extra!$O$3))* SIN(RADIANS(extra!$P$3-J33)/2)^2 ) ) -> 101.12117 | V33: =2*6371000*ASIN( SQRT( SIN(RADIANS(extra!$O$4-I33)/2)^2+ COS(RADIANS(I33))*COS(RADIANS(extra!$O$4))* SIN(RADIANS(extra!$P$4-J33)/2)^2 ) ) -> 278.11322 | W33: =MIN(Q33:V33) -> 101.12117
... A44: 60 | B44: 2994447547 | C44: !dadfb8d4 | D44: 1784213355.839594 | E44: 1784213367.0156832 | F44: =E44-D44 -> 11.17609 | G44: -78 | H44: 8.25 | I44: 44.637745 | J44: -63.59221 | K44: 49 | L44: 7 | M44: 4 | N44: =L44-M44 -> 3 | Q44: =2*6371000*ASIN( SQRT( SIN(RADIANS(extra!$O$2-I44)/2)^2+ COS(RADIANS(I44))*COS(RADIANS(extra!$O$2))* SIN(RADIANS(extra!$P$2-J44)/2)^2 ) ) -> 392.7101 | R44: =2*6371000*ASIN( SQRT( SIN(RADIANS(extra!$O$7-I44)/2)^2+ COS(RADIANS(I44))*COS(RADIANS(extra!$O$7))* SIN(RADIANS(extra!$P$7-J44)/2)^2 ) ) -> 373.57396 | S44: =2*6371000*ASIN( SQRT( SIN(RADIANS(extra!$O$5-I44)/2)^2+ COS(RADIANS(I44))*COS(RADIANS(extra!$O$5))* SIN(RADIANS(extra!$P$5-J44)/2)^2 ) ) -> 303.05976 | T44: =2*6371000*ASIN( SQRT( SIN(RADIANS(extra!$O$6-I44)/2)^2+ COS(RADIANS(I44))*COS(RADIANS(extra!$O$6))* SIN(RADIANS(extra!$P$6-J44)/2)^2 ) ) -> 164.6943 | U44: =2*6371000*ASIN( SQRT( SIN(RADIANS(extra!$O$3-I44)/2)^2+ COS(RADIANS(I44))*COS(RADIANS(extra!$O$3))* SIN(RADIANS(extra!$P$3-J44)/2)^2 ) ) -> 234.64037 | V44: =2*6371000*ASIN( SQRT( SIN(RADIANS(extra!$O$4-I44)/2)^2+ COS(RADIANS(I44))*COS(RADIANS(extra!$O$4))* SIN(RADIANS(extra!$P$4-J44)/2)^2 ) ) -> 82.083854 | W44: =MIN(Q44:V44) -> 82.083854
A45: 61 | B45: 3912256700 | C45: !dadfb8d4 | D45: 1.7842134e+09 | E45: 1784213382.9408088 | F45: =E45-D45 -> 6.9728498 | G45: -79 | H45: 8.75 | I45: 44.637855 | J45: -63.591819 | K45: 51 | L45: 7 | M45: 5 | N45: =L45-M45 -> 2 | Q45: =2*6371000*ASIN( SQRT( SIN(RADIANS(extra!$O$2-I45)/2)^2+ COS(RADIANS(I45))*COS(RADIANS(extra!$O$2))* SIN(RADIANS(extra!$P$2-J45)/2)^2 ) ) -> 363.34982 | R45: =2*6371000*ASIN( SQRT( SIN(RADIANS(extra!$O$7-I45)/2)^2+ COS(RADIANS(I45))*COS(RADIANS(extra!$O$7))* SIN(RADIANS(extra!$P$7-J45)/2)^2 ) ) -> 344.27474 | S45: =2*6371000*ASIN( SQRT( SIN(RADIANS(extra!$O$5-I45)/2)^2+ COS(RADIANS(I45))*COS(RADIANS(extra!$O$5))* SIN(RADIANS(extra!$P$5-J45)/2)^2 ) ) -> 275.86751 | T45: =2*6371000*ASIN( SQRT( SIN(RADIANS(extra!$O$6-I45)/2)^2+ COS(RADIANS(I45))*COS(RADIANS(extra!$O$6))* SIN(RADIANS(extra!$P$6-J45)/2)^2 ) ) -> 134.65859 | U45: =2*6371000*ASIN( SQRT( SIN(RADIANS(extra!$O$3-I45)/2)^2+ COS(RADIANS(I45))*COS(RADIANS(extra!$O$3))* SIN(RADIANS(extra!$P$3-J45)/2)^2 ) ) -> 264.37596 | V45: =2*6371000*ASIN( SQRT( SIN(RADIANS(extra!$O$4-I45)/2)^2+ COS(RADIANS(I45))*COS(RADIANS(extra!$O$4))* SIN(RADIANS(extra!$P$4-J45)/2)^2 ) ) -> 115.03435 | W45: =MIN(Q45:V45) -> 115.03435
A46: 62 | B46: 2726708413 | C46: !dadfb8d4 | D46: 1784213396.096748 | E46: 1784213402.9714687 | F46: =E46-D46 -> 6.8747201 | G46: -80 | H46: 8.75 | I46: 44.637957 | J46: -63.591443 | K46: 53 | L46: 7 | M46: 5 | N46: =L46-M46 -> 2 | Q46: =2*6371000*ASIN( SQRT( SIN(RADIANS(extra!$O$2-I46)/2)^2+ COS(RADIANS(I46))*COS(RADIANS(extra!$O$2))* SIN(RADIANS(extra!$P$2-J46)/2)^2 ) ) -> 335.72866 | R46: =2*6371000*ASIN( SQRT( SIN(RADIANS(extra!$O$7-I46)/2)^2+ COS(RADIANS(I46))*COS(RADIANS(extra!$O$7))* SIN(RADIANS(extra!$P$7-J46)/2)^2 ) ) -> 316.76077 | S46: =2*6371000*ASIN( SQRT( SIN(RADIANS(extra!$O$5-I46)/2)^2+ COS(RADIANS(I46))*COS(RADIANS(extra!$O$5))* SIN(RADIANS(extra!$P$5-J46)/2)^2 ) ) -> 250.95881 | T46: =2*6371000*ASIN( SQRT( SIN(RADIANS(extra!$O$6-I46)/2)^2+ COS(RADIANS(I46))*COS(RADIANS(extra!$O$6))* SIN(RADIANS(extra!$P$6-J46)/2)^2 ) ) -> 107.47647 | U46: =2*6371000*ASIN( SQRT( SIN(RADIANS(extra!$O$3-I46)/2)^2+ COS(RADIANS(I46))*COS(RADIANS(extra!$O$3))* SIN(RADIANS(extra!$P$3-J46)/2)^2 ) ) -> 293.39485 | V46: =2*6371000*ASIN( SQRT( SIN(RADIANS(extra!$O$4-I46)/2)^2+ COS(RADIANS(I46))*COS(RADIANS(extra!$O$4))* SIN(RADIANS(extra!$P$4-J46)/2)^2 ) ) -> 146.73759 | W46: =MIN(Q46:V46) -> 107.47647
A47: 63 | B47: 1022406846 | C47: !dadfb8d4 | D47: 1784213416.217118 | E47: 1784213425.8801286 | F47: =E47-D47 -> 9.6630101 | G47: -80 | H47: 8.25 | I47: 44.638105 | J47: -63.591064 | K47: 56 | L47: 7 | M47: 5 | N47: =L47-M47 -> 2 | Q47: =2*6371000*ASIN( SQRT( SIN(RADIANS(extra!$O$2-I47)/2)^2+ COS(RADIANS(I47))*COS(RADIANS(extra!$O$2))* SIN(RADIANS(extra!$P$2-J47)/2)^2 ) ) -> 309.91037 | R47: =2*6371000*ASIN( SQRT( SIN(RADIANS(extra!$O$7-I47)/2)^2+ COS(RADIANS(I47))*COS(RADIANS(extra!$O$7))* SIN(RADIANS(extra!$P$7-J47)/2)^2 ) ) -> 291.18873 | S47: =2*6371000*ASIN( SQRT( SIN(RADIANS(extra!$O$5-I47)/2)^2+ COS(RADIANS(I47))*COS(RADIANS(extra!$O$5))* SIN(RADIANS(extra!$P$5-J47)/2)^2 ) ) -> 229.78682 | T47: =2*6371000*ASIN( SQRT( SIN(RADIANS(extra!$O$6-I47)/2)^2+ COS(RADIANS(I47))*COS(RADIANS(extra!$O$6))* SIN(RADIANS(extra!$P$6-J47)/2)^2 ) ) -> 85.921823 | U47: =2*6371000*ASIN( SQRT( SIN(RADIANS(extra!$O$3-I47)/2)^2+ COS(RADIANS(I47))*COS(RADIANS(extra!$O$3))* SIN(RADIANS(extra!$P$3-J47)/2)^2 ) ) -> 326.54246 | V47: =2*6371000*ASIN( SQRT( SIN(RADIANS(extra!$O$4-I47)/2)^2+ COS(RADIANS(I47))*COS(RADIANS(extra!$O$4))* SIN(RADIANS(extra!$P$4-J47)/2)^2 ) ) -> 180.27799 | W47: =MIN(Q47:V47) -> 85.921823
A48: 64 | B48: 3308797119 | C48: !dadfb8d4 | D48: 1784213436.3352802 | E48: 1784213444.430764 | F48: =E48-D48 -> 8.09548 | G48: -77 | H48: 9 | I48: 44.638209 | J48: -63.590701 | K48: 56 | L48: 7 | M48: 5 | N48: =L48-M48 -> 2 | Q48: =2*6371000*ASIN( SQRT( SIN(RADIANS(extra!$O$2-I48)/2)^2+ COS(RADIANS(I48))*COS(RADIANS(extra!$O$2))* SIN(RADIANS(extra!$P$2-J48)/2)^2 ) ) -> 285.51176 | R48: =2*6371000*ASIN( SQRT( SIN(RADIANS(extra!$O$7-I48)/2)^2+ COS(RADIANS(I48))*COS(RADIANS(extra!$O$7))* SIN(RADIANS(extra!$P$7-J48)/2)^2 ) ) -> 267.10542 | S48: =2*6371000*ASIN( SQRT( SIN(RADIANS(extra!$O$5-I48)/2)^2+ COS(RADIANS(I48))*COS(RADIANS(extra!$O$5))* SIN(RADIANS(extra!$P$5-J48)/2)^2 ) ) -> 210.42467 | T48: =2*6371000*ASIN( SQRT( SIN(RADIANS(extra!$O$6-I48)/2)^2+ COS(RADIANS(I48))*COS(RADIANS(extra!$O$6))* SIN(RADIANS(extra!$P$6-J48)/2)^2 ) ) -> 71.430806 | U48: =2*6371000*ASIN( SQRT( SIN(RADIANS(extra!$O$3-I48)/2)^2+ COS(RADIANS(I48))*COS(RADIANS(extra!$O$3))* SIN(RADIANS(extra!$P$3-J48)/2)^2 ) ) -> 355.73378 | V48: =2*6371000*ASIN( SQRT( SIN(RADIANS(extra!$O$4-I48)/2)^2+ COS(RADIANS(I48))*COS(RADIANS(extra!$O$4))* SIN(RADIANS(extra!$P$4-J48)/2)^2 ) ) -> 211.19405 | W48: =MIN(Q48:V48) -> 71.430806
A49: 66 | B49: 1411102913 | C49: !dadfb8d4 | D49: 1784213476.586934 | E49: 1784213489.0034916 | F49: =E49-D49 -> 12.41656 | G49: -79 | H49: 8.25 | I49: 44.638692 | J49: -63.59088 | K49: 56 | L49: 7 | M49: 5 | N49: =L49-M49 -> 2 | Q49: =2*6371000*ASIN( SQRT( SIN(RADIANS(extra!$O$2-I49)/2)^2+ COS(RADIANS(I49))*COS(RADIANS(extra!$O$2))* SIN(RADIANS(extra!$P$2-J49)/2)^2 ) ) -> 318.97176 | R49: =2*6371000*ASIN( SQRT( SIN(RADIANS(extra!$O$7-I49)/2)^2+ COS(RADIANS(I49))*COS(RADIANS(extra!$O$7))* SIN(RADIANS(extra!$P$7-J49)/2)^2 ) ) -> 301.57162 | S49: =2*6371000*ASIN( SQRT( SIN(RADIANS(extra!$O$5-I49)/2)^2+ COS(RADIANS(I49))*COS(RADIANS(extra!$O$5))* SIN(RADIANS(extra!$P$5-J49)/2)^2 ) ) -> 254.08005 | T49: =2*6371000*ASIN( SQRT( SIN(RADIANS(extra!$O$6-I49)/2)^2+ COS(RADIANS(I49))*COS(RADIANS(extra!$O$6))* SIN(RADIANS(extra!$P$6-J49)/2)^2 ) ) -> 124.11874 | U49: =2*6371000*ASIN( SQRT( SIN(RADIANS(extra!$O$3-I49)/2)^2+ COS(RADIANS(I49))*COS(RADIANS(extra!$O$3))* SIN(RADIANS(extra!$P$3-J49)/2)^2 ) ) -> 383.16877 | V49: =2*6371000*ASIN( SQRT( SIN(RADIANS(extra!$O$4-I49)/2)^2+ COS(RADIANS(I49))*COS(RADIANS(extra!$O$4))* SIN(RADIANS(extra!$P$4-J49)/2)^2 ) ) -> 222.34749 | W49: =MIN(Q49:V49) -> 124.11874
A50: 68 | B50: 3084971203 | C50: !dadfb8d4 | D50: 1784213516.823911 | E50: 1784213529.6268787 | F50: =E50-D50 -> 12.80296 | G50: -82 | H50: 7.5 | I50: 44.639196 | J50: -63.590604 | K50: 57 | L50: 7 | M50: 4 | N50: =L50-M50 -> 3 | Q50: =2*6371000*ASIN( SQRT( SIN(RADIANS(extra!$O$2-I50)/2)^2+ COS(RADIANS(I50))*COS(RADIANS(extra!$O$2))* SIN(RADIANS(extra!$P$2-J50)/2)^2 ) ) -> 329.78218 | R50: =2*6371000*ASIN( SQRT( SIN(RADIANS(extra!$O$7-I50)/2)^2+ COS(RADIANS(I50))*COS(RADIANS(extra!$O$7))* SIN(RADIANS(extra!$P$7-J50)/2)^2 ) ) -> 314.17806 | S50: =2*6371000*ASIN( SQRT( SIN(RADIANS(extra!$O$5-I50)/2)^2+ COS(RADIANS(I50))*COS(RADIANS(extra!$O$5))* SIN(RADIANS(extra!$P$5-J50)/2)^2 ) ) -> 280.23395 | T50: =2*6371000*ASIN( SQRT( SIN(RADIANS(extra!$O$6-I50)/2)^2+ COS(RADIANS(I50))*COS(RADIANS(extra!$O$6))* SIN(RADIANS(extra!$P$6-J50)/2)^2 ) ) -> 169.23898 | U50: =2*6371000*ASIN( SQRT( SIN(RADIANS(extra!$O$3-I50)/2)^2+ COS(RADIANS(I50))*COS(RADIANS(extra!$O$3))* SIN(RADIANS(extra!$P$3-J50)/2)^2 ) ) -> 439.95993 | V50: =2*6371000*ASIN( SQRT( SIN(RADIANS(extra!$O$4-I50)/2)^2+ COS(RADIANS(I50))*COS(RADIANS(extra!$O$4))* SIN(RADIANS(extra!$P$4-J50)/2)^2 ) ) -> 273.68346 | W50: =MIN(Q50:V50) -> 169.23898
A51: 70 | B51: 2686406853 | C51: !dadfb8d4 | D51: 1784213557.069551 | E51: 1784213564.4606628 | F51: =E51-D51 -> 7.3911099 | G51: -83 | H51: 9.75 | I51: 44.639425 | J51: -63.589847 | K51: 58 | L51: 7 | M51: 5 | N51: =L51-M51 -> 2 | Q51: =2*6371000*ASIN( SQRT( SIN(RADIANS(extra!$O$2-I51)/2)^2+ COS(RADIANS(I51))*COS(RADIANS(extra!$O$2))* SIN(RADIANS(extra!$P$2-J51)/2)^2 ) ) -> 302.39383 | R51: =2*6371000*ASIN( SQRT( SIN(RADIANS(extra!$O$7-I51)/2)^2+ COS(RADIANS(I51))*COS(RADIANS(extra!$O$7))* SIN(RADIANS(extra!$P$7-J51)/2)^2 ) ) -> 289.21905 | S51: =2*6371000*ASIN( SQRT( SIN(RADIANS(extra!$O$5-I51)/2)^2+ COS(RADIANS(I51))*COS(RADIANS(extra!$O$5))* SIN(RADIANS(extra!$P$5-J51)/2)^2 ) ) -> 271.67206 | T51: =2*6371000*ASIN( SQRT( SIN(RADIANS(extra!$O$6-I51)/2)^2+ COS(RADIANS(I51))*COS(RADIANS(extra!$O$6))* SIN(RADIANS(extra!$P$6-J51)/2)^2 ) ) -> 191.77926 | U51: =2*6371000*ASIN( SQRT( SIN(RADIANS(extra!$O$3-I51)/2)^2+ COS(RADIANS(I51))*COS(RADIANS(extra!$O$3))* SIN(RADIANS(extra!$P$3-J51)/2)^2 ) ) -> 498.46257 | V51: =2*6371000*ASIN( SQRT( SIN(RADIANS(extra!$O$4-I51)/2)^2+ COS(RADIANS(I51))*COS(RADIANS(extra!$O$4))* SIN(RADIANS(extra!$P$4-J51)/2)^2 ) ) -> 336.2596 | W51: =MIN(Q51:V51) -> 191.77926
A52: 71 | B52: 3789574342 | C52: !dadfb8d4 | D52: 1784213577.1984158 | E52: 1784213585.444266 | F52: =E52-D52 -> 8.2458498 | G52: -83 | H52: 9.75 | I52: 44.638985 | J52: -63.589779 | K52: 55 | L52: 7 | M52: 5 | N52: =L52-M52 -> 2 | Q52: =2*6371000*ASIN( SQRT( SIN(RADIANS(extra!$O$2-I52)/2)^2+ COS(RADIANS(I52))*COS(RADIANS(extra!$O$2))* SIN(RADIANS(extra!$P$2-J52)/2)^2 ) ) -> 264.25732 | R52: =2*6371000*ASIN( SQRT( SIN(RADIANS(extra!$O$7-I52)/2)^2+ COS(RADIANS(I52))*COS(RADIANS(extra!$O$7))* SIN(RADIANS(extra!$P$7-J52)/2)^2 ) ) -> 249.63915 | S52: =2*6371000*ASIN( SQRT( SIN(RADIANS(extra!$O$5-I52)/2)^2+ COS(RADIANS(I52))*COS(RADIANS(extra!$O$5))* SIN(RADIANS(extra!$P$5-J52)/2)^2 ) ) -> 225.23203 | T52: =2*6371000*ASIN( SQRT( SIN(RADIANS(extra!$O$6-I52)/2)^2+ COS(RADIANS(I52))*COS(RADIANS(extra!$O$6))* SIN(RADIANS(extra!$P$6-J52)/2)^2 ) ) -> 144.23453 | U52: =2*6371000*ASIN( SQRT( SIN(RADIANS(extra!$O$3-I52)/2)^2+ COS(RADIANS(I52))*COS(RADIANS(extra!$O$3))* SIN(RADIANS(extra!$P$3-J52)/2)^2 ) ) -> 467.61262 | V52: =2*6371000*ASIN( SQRT( SIN(RADIANS(extra!$O$4-I52)/2)^2+ COS(RADIANS(I52))*COS(RADIANS(extra!$O$4))* SIN(RADIANS(extra!$P$4-J52)/2)^2 ) ) -> 313.67516 | W52: =MIN(Q52:V52) -> 144.23453
A53: 73 | B53: 836387016 | C53: !dadfb8d4 | D53: 1784213617.480107 | E53: 1784213624.5860066 | F53: =E53-D53 -> 7.1059 | G53: -86 | H53: 7.25 | I53: 44.638535 | J53: -63.589439 | K53: 55 | L53: 7 | M53: 5 | N53: =L53-M53 -> 2 | Q53: =2*6371000*ASIN( SQRT( SIN(RADIANS(extra!$O$2-I53)/2)^2+ COS(RADIANS(I53))*COS(RADIANS(extra!$O$2))* SIN(RADIANS(extra!$P$2-J53)/2)^2 ) ) -> 211.97409 | R53: =2*6371000*ASIN( SQRT( SIN(RADIANS(extra!$O$7-I53)/2)^2+ COS(RADIANS(I53))*COS(RADIANS(extra!$O$7))* SIN(RADIANS(extra!$P$7-J53)/2)^2 ) ) -> 196.28758 | S53: =2*6371000*ASIN( SQRT( SIN(RADIANS(extra!$O$5-I53)/2)^2+ COS(RADIANS(I53))*COS(RADIANS(extra!$O$5))* SIN(RADIANS(extra!$P$5-J53)/2)^2 ) ) -> 168.42648 | T53: =2*6371000*ASIN( SQRT( SIN(RADIANS(extra!$O$6-I53)/2)^2+ COS(RADIANS(I53))*COS(RADIANS(extra!$O$6))* SIN(RADIANS(extra!$P$6-J53)/2)^2 ) ) -> 106.56083 | U53: =2*6371000*ASIN( SQRT( SIN(RADIANS(extra!$O$3-I53)/2)^2+ COS(RADIANS(I53))*COS(RADIANS(extra!$O$3))* SIN(RADIANS(extra!$P$3-J53)/2)^2 ) ) -> 456.70117 | V53: =2*6371000*ASIN( SQRT( SIN(RADIANS(extra!$O$4-I53)/2)^2+ COS(RADIANS(I53))*COS(RADIANS(extra!$O$4))* SIN(RADIANS(extra!$P$4-J53)/2)^2 ) ) -> 317.41283 | W53: =MIN(Q53:V53) -> 106.56083
A54: 74 | B54: 920919241 | C54: !dadfb8d4 | D54: 1784213637.5995688 | E54: 1784213643.0310507 | F54: =E54-D54 -> 5.4314899 | G54: -79 | H54: 8.5 | I54: 44.638281 | J54: -63.589262 | K54: 55 | L54: 7 | M54: 6 | N54: =L54-M54 -> 1 | Q54: =2*6371000*ASIN( SQRT( SIN(RADIANS(extra!$O$2-I54)/2)^2+ COS(RADIANS(I54))*COS(RADIANS(extra!$O$2))* SIN(RADIANS(extra!$P$2-J54)/2)^2 ) ) -> 184.66119 | R54: =2*6371000*ASIN( SQRT( SIN(RADIANS(extra!$O$7-I54)/2)^2+ COS(RADIANS(I54))*COS(RADIANS(extra!$O$7))* SIN(RADIANS(extra!$P$7-J54)/2)^2 ) ) -> 168.15411 | S54: =2*6371000*ASIN( SQRT( SIN(RADIANS(extra!$O$5-I54)/2)^2+ COS(RADIANS(I54))*COS(RADIANS(extra!$O$5))* SIN(RADIANS(extra!$P$5-J54)/2)^2 ) ) -> 136.90754 | T54: =2*6371000*ASIN( SQRT( SIN(RADIANS(extra!$O$6-I54)/2)^2+ COS(RADIANS(I54))*COS(RADIANS(extra!$O$6))* SIN(RADIANS(extra!$P$6-J54)/2)^2 ) ) -> 93.321276 | U54: =2*6371000*ASIN( SQRT( SIN(RADIANS(extra!$O$3-I54)/2)^2+ COS(RADIANS(I54))*COS(RADIANS(extra!$O$3))* SIN(RADIANS(extra!$P$3-J54)/2)^2 ) ) -> 452.57651 | V54: =2*6371000*ASIN( SQRT( SIN(RADIANS(extra!$O$4-I54)/2)^2+ COS(RADIANS(I54))*COS(RADIANS(extra!$O$4))* SIN(RADIANS(extra!$P$4-J54)/2)^2 ) ) -> 322.78681 | W54: =MIN(Q54:V54) -> 93.321276
A55: 75 | B55: 4071558346 | C55: !dadfb8d4 | D55: 1784213657.7219431 | E55: 1784213670.2931454 | F55: =E55-D55 -> 12.5712 | G55: -80 | H55: 8 | I55: 44.638051 | J55: -63.589108 | K55: 55 | L55: 7 | M55: 6 | N55: =L55-M55 -> 1 | Q55: =2*6371000*ASIN( SQRT( SIN(RADIANS(extra!$O$2-I55)/2)^2+ COS(RADIANS(I55))*COS(RADIANS(extra!$O$2))* SIN(RADIANS(extra!$P$2-J55)/2)^2 ) ) -> 161.70719 | R55: =2*6371000*ASIN( SQRT( SIN(RADIANS(extra!$O$7-I55)/2)^2+ COS(RADIANS(I55))*COS(RADIANS(extra!$O$7))* SIN(RADIANS(extra!$P$7-J55)/2)^2 ) ) -> 144.33184 | S55: =2*6371000*ASIN( SQRT( SIN(RADIANS(extra!$O$5-I55)/2)^2+ COS(RADIANS(I55))*COS(RADIANS(extra!$O$5))* SIN(RADIANS(extra!$P$5-J55)/2)^2 ) ) -> 108.60328 | T55: =2*6371000*ASIN( SQRT( SIN(RADIANS(extra!$O$6-I55)/2)^2+ COS(RADIANS(I55))*COS(RADIANS(extra!$O$6))* SIN(RADIANS(extra!$P$6-J55)/2)^2 ) ) -> 89.145446 | U55: =2*6371000*ASIN( SQRT( SIN(RADIANS(extra!$O$3-I55)/2)^2+ COS(RADIANS(I55))*COS(RADIANS(extra!$O$3))* SIN(RADIANS(extra!$P$3-J55)/2)^2 ) ) -> 450.27823 | V55: =2*6371000*ASIN( SQRT( SIN(RADIANS(extra!$O$4-I55)/2)^2+ COS(RADIANS(I55))*COS(RADIANS(extra!$O$4))* SIN(RADIANS(extra!$P$4-J55)/2)^2 ) ) -> 329.69361 | W55: =MIN(Q55:V55) -> 89.145446
...

Sheet extra
A1: latency | B1: hopsUsed | D1: hopsUsed | E1: avg. latency | H1: latency | I1: hopsUsed | J1: avg latency | K1: hopsUsed | L1: avg latency/number of edges | M1: expected latency for 1 connection | N1: node | O1: lat | P1: lon
A2: =dynamic_test_3hop!E2-dynamic_test_3hop!D2 -> 2.30195 | B2: =dynamic_test_3hop!L2-dynamic_test_3hop!M2 -> 0 | D2: 0 | E2: =AVERAGE(A2:A9) -> 1.9413837 | H2: =dynamic_test_7hop!E2-dynamic_test_7hop!D2 -> 1.84954 | I2: =dynamic_test_7hop!L2-dynamic_test_7hop!M2 -> 0 | J2: =AVERAGE(H2:H22) -> 2.1130033 | K2: 0 | L2: =J2 -> 2.1130033 | M2: =AVERAGE(L2:L7) -> 2.6219301 | N2: !ea2468b0 | O2: 44.637418 | P2: -63.587268 | U2: 1
A3: =dynamic_test_3hop!E3-dynamic_test_3hop!D3 -> 2.1058402 | B3: =dynamic_test_3hop!L3-dynamic_test_3hop!M3 -> 0 | D3: 1 | E3: =AVERAGE(A10:A18) -> 4.1686045 | H3: =dynamic_test_7hop!E3-dynamic_test_7hop!D3 -> 2.0892601 | I3: =dynamic_test_7hop!L3-dynamic_test_7hop!M3 -> 0 | J3: =AVERAGE(H23:H33) -> 6.5061482 | K3: 1 | L3: =J3/2 -> 3.2530741 | N3: !dadfb008 | O3: 44.636129 | P3: -63.594117 | U3: 2
A4: =dynamic_test_3hop!E4-dynamic_test_3hop!D4 -> 1.9674799 | B4: =dynamic_test_3hop!L4-dynamic_test_3hop!M4 -> 0 | D4: 2 | E4: =AVERAGE(A19:A23) -> 7.865358 | H4: =dynamic_test_7hop!E4-dynamic_test_7hop!D4 -> 1.7227399 | I4: =dynamic_test_7hop!L4-dynamic_test_7hop!M4 -> 0 | J4: =AVERAGE(H34:H46) -> 8.0732392 | K4: 2 | L4: =J4/3 -> 2.6910797 | N4: !dadfb03c | O4: 44.637589 | P4: -63.593224 | U4: 3
A5: =dynamic_test_3hop!E5-dynamic_test_3hop!D5 -> 1.9147401 | B5: =dynamic_test_3hop!L5-dynamic_test_3hop!M5 -> 0 | D5: 3 | E5: =AVERAGE(A24:A27) -> 8.58846 | H5: =dynamic_test_7hop!E5-dynamic_test_7hop!D5 -> 2.57741 | I5: =dynamic_test_7hop!L5-dynamic_test_7hop!M5 -> 0 | J5: =AVERAGE(H47:H61) -> 9.982436 | K5: 3 | L5: =J5/4 -> 2.495609 | N5: !dadfb0cc | O5: 44.63719 | P5: -63.58846 | U5: 4
A6: =dynamic_test_3hop!E24-dynamic_test_3hop!D24 -> 1.7644999 | B6: =dynamic_test_3hop!L24-dynamic_test_3hop!M24 -> 0 | H6: =dynamic_test_7hop!E6-dynamic_test_7hop!D6 -> 1.92995 | I6: =dynamic_test_7hop!L6-dynamic_test_7hop!M6 -> 0 | J6: =AVERAGE(H62) -> 11.98678 | K6: 4 | L6: =J6/5 -> 2.397356 | N6: !dadfb6c8 | O6: 44.637712 | P6: -63.590129 | U6: 5
A7: =dynamic_test_3hop!E25-dynamic_test_3hop!D25 -> 1.9056299 | B7: =dynamic_test_3hop!L25-dynamic_test_3hop!M25 -> 0 | H7: =dynamic_test_7hop!E7-dynamic_test_7hop!D7 -> 2.01546 | I7: =dynamic_test_7hop!L7-dynamic_test_7hop!M7 -> 0 | J7: =AVERAGE(H63) -> 16.68875 | K7: 5 | L7: =J7/6 -> 2.7814583 | N7: !6c73daa0 | O7: 44.637425 | P7: -63.58751 | U7: 6
A8: =dynamic_test_3hop!E26-dynamic_test_3hop!D26 -> 1.7715299 | B8: =dynamic_test_3hop!L26-dynamic_test_3hop!M26 -> 0 | H8: =dynamic_test_7hop!E8-dynamic_test_7hop!D8 -> 3.5180302 | I8: =dynamic_test_7hop!L8-dynamic_test_7hop!M8 -> 0
A9: =dynamic_test_3hop!E27-dynamic_test_3hop!D27 -> 1.7993999 | B9: =dynamic_test_3hop!L27-dynamic_test_3hop!M27 -> 0 | H9: =dynamic_test_7hop!E9-dynamic_test_7hop!D9 -> 1.8910499 | I9: =dynamic_test_7hop!L9-dynamic_test_7hop!M9 -> 0
A10: =dynamic_test_3hop!E6-dynamic_test_3hop!D6 -> 4.75176 | B10: =dynamic_test_3hop!L6-dynamic_test_3hop!M6 -> 1 | H10: =dynamic_test_7hop!E10-dynamic_test_7hop!D10 -> 1.9503901 | I10: =dynamic_test_7hop!L10-dynamic_test_7hop!M10 -> 0
A11: =dynamic_test_3hop!E7-dynamic_test_3hop!D7 -> 4.1999002 | B11: =dynamic_test_3hop!L7-dynamic_test_3hop!M7 -> 1 | H11: =dynamic_test_7hop!E11-dynamic_test_7hop!D11 -> 1.8908598 | I11: =dynamic_test_7hop!L11-dynamic_test_7hop!M11 -> 0
A12: =dynamic_test_3hop!E13-dynamic_test_3hop!D13 -> 4.11375 | B12: =dynamic_test_3hop!L13-dynamic_test_3hop!M13 -> 1 | H12: =dynamic_test_7hop!E12-dynamic_test_7hop!D12 -> 1.86672 | I12: =dynamic_test_7hop!L12-dynamic_test_7hop!M12 -> 0
A13: =dynamic_test_3hop!E14-dynamic_test_3hop!D14 -> 4.3341701 | B13: =dynamic_test_3hop!L14-dynamic_test_3hop!M14 -> 1 | H13: =dynamic_test_7hop!E13-dynamic_test_7hop!D13 -> 2.1085601 | I13: =dynamic_test_7hop!L13-dynamic_test_7hop!M13 -> 0
A14: =dynamic_test_3hop!E15-dynamic_test_3hop!D15 -> 3.7421598 | B14: =dynamic_test_3hop!L15-dynamic_test_3hop!M15 -> 1 | H14: =dynamic_test_7hop!E22-dynamic_test_7hop!D22 -> 2.1308599 | I14: =dynamic_test_7hop!L22-dynamic_test_7hop!M22 -> 0
A15: =dynamic_test_3hop!E18-dynamic_test_3hop!D18 -> 3.82829 | B15: =dynamic_test_3hop!L18-dynamic_test_3hop!M18 -> 1 | H15: =dynamic_test_7hop!E56-dynamic_test_7hop!D56 -> 2.2323799 | I15: =dynamic_test_7hop!L56-dynamic_test_7hop!M56 -> 0
A16: =dynamic_test_3hop!E21-dynamic_test_3hop!D21 -> 4.2176499 | B16: =dynamic_test_3hop!L21-dynamic_test_3hop!M21 -> 1 | H16: =dynamic_test_7hop!E57-dynamic_test_7hop!D57 -> 2.02265 | I16: =dynamic_test_7hop!L57-dynamic_test_7hop!M57 -> 0
A17: =dynamic_test_3hop!E22-dynamic_test_3hop!D22 -> 4.0689402 | B17: =dynamic_test_3hop!L22-dynamic_test_3hop!M22 -> 1 | H17: =dynamic_test_7hop!E58-dynamic_test_7hop!D58 -> 2.20439 | I17: =dynamic_test_7hop!L58-dynamic_test_7hop!M58 -> 0
A18: =dynamic_test_3hop!E23-dynamic_test_3hop!D23 -> 4.2608199 | B18: =dynamic_test_3hop!L23-dynamic_test_3hop!M23 -> 1 | H18: =dynamic_test_7hop!E59-dynamic_test_7hop!D59 -> 2.0721798 | I18: =dynamic_test_7hop!L59-dynamic_test_7hop!M59 -> 0
A19: =dynamic_test_3hop!E8-dynamic_test_3hop!D8 -> 7.30021 | B19: =dynamic_test_3hop!L8-dynamic_test_3hop!M8 -> 2 | H19: =dynamic_test_7hop!E60-dynamic_test_7hop!D60 -> 2.0957499 | I19: =dynamic_test_7hop!L60-dynamic_test_7hop!M60 -> 0
A20: =dynamic_test_3hop!E12-dynamic_test_3hop!D12 -> 7.0053699 | B20: =dynamic_test_3hop!L12-dynamic_test_3hop!M12 -> 2 | H20: =dynamic_test_7hop!E61-dynamic_test_7hop!D61 -> 2.1098599 | I20: =dynamic_test_7hop!L61-dynamic_test_7hop!M61 -> 0
A21: =dynamic_test_3hop!E16-dynamic_test_3hop!D16 -> 10.03901 | B21: =dynamic_test_3hop!L16-dynamic_test_3hop!M16 -> 2 | H21: =dynamic_test_7hop!E62-dynamic_test_7hop!D62 -> 2.11854 | I21: =dynamic_test_7hop!L62-dynamic_test_7hop!M62 -> 0
A22: =dynamic_test_3hop!E17-dynamic_test_3hop!D17 -> 6.69261 | B22: =dynamic_test_3hop!L17-dynamic_test_3hop!M17 -> 2 | H22: =dynamic_test_7hop!E63-dynamic_test_7hop!D63 -> 1.97649 | I22: =dynamic_test_7hop!L63-dynamic_test_7hop!M63 -> 0
A23: =dynamic_test_3hop!E20-dynamic_test_3hop!D20 -> 8.2895899 | B23: =dynamic_test_3hop!L20-dynamic_test_3hop!M20 -> 2 | H23: =dynamic_test_7hop!E14-dynamic_test_7hop!D14 -> 5.56233 | I23: =dynamic_test_7hop!L14-dynamic_test_7hop!M14 -> 1
A24: =dynamic_test_3hop!E9-dynamic_test_3hop!D9 -> 8.2244201 | B24: =dynamic_test_3hop!L9-dynamic_test_3hop!M9 -> 3 | H24: =dynamic_test_7hop!E15-dynamic_test_7hop!D15 -> 4.2294898 | I24: =dynamic_test_7hop!L15-dynamic_test_7hop!M15 -> 1
